Workbook

Sheet DASHBOARD
A1: SkyLimit AR AGING DASHBOARD
A2: As of 25-May-2026 | Automated AR Aging Report
A4: Total Outstanding | C4: Total Collected | E4: Total Pending | G4: Total Customers | I4: Total Invoices | K4: DSO Actions
A5: =SUMIFS(MASTER_AR_REPORT!I:I,MASTER_AR_REPORT!I:I,">0") | C5: =SUM(MASTER_AR_REPORT!H:H) | E5: =SUMIFS(MASTER_AR_REPORT!I:I,MASTER_AR_REPORT!I:I,">0") | G5: =SUMPRODUCT((MASTER_AR_REPORT!A2:A99999<>"")*(MASTER_AR_REPORT!B2:B99999<>""))/2 | I5: =COUNTA(MASTER_AR_REPORT!A2:A99999) | K5: =COUNTA('DSO Actions'!A2:A99999)
A7: High Risk (90+) | C7: Medium Risk (31-90) | E7: Low Risk (0-30) | G7: Calling List | I7: Overdue > 90 Days | K7: Collection Rate
A8: =SUMIFS(MASTER_AR_REPORT!I:I,MASTER_AR_REPORT!L:L,"HIGH RISK") | C8: =SUMIFS(MASTER_AR_REPORT!I:I,MASTER_AR_REPORT!L:L,"Medium")+SUMIFS(MASTER_AR_REPORT!I:I,MASTER_AR_REPORT!L:L,"Low-Medium") | E8: =SUMIFS(MASTER_AR_REPORT!I:I,MASTER_AR_REPORT!L:L,"Low")+SUMIFS(MASTER_AR_REPORT!I:I,MASTER_AR_REPORT!L:L,"-") | G8: =COUNTA(CALLING_LIST!A5:A99999) | I8: =COUNTIFS(MASTER_AR_REPORT!J:J,">90",MASTER_AR_REPORT!I:I,">0") | K8: =IF(SUM(MASTER_AR_REPORT!F:F)=0,0,SUM(MASTER_AR_REPORT!H:H)/SUM(MASTER_AR_REPORT!F:F))
A10: AGING BUCKET SUMMARY
A11: Aging Bucket | B11: Invoice Count | C11: Total Amount | D11: % of Total | E11: Avg Days Overdue
A12: Current | B12: =COUNTIFS(MASTER_AR_REPORT!K:K,"Current",MASTER_AR_REPORT!I:I,">0") | C12: =SUMIFS(MASTER_AR_REPORT!I:I,MASTER_AR_REPORT!K:K,"Current") | D12: =IF(C$17=0,0,C12/C$17) | E12: =IFERROR(AVERAGEIFS(MASTER_AR_REPORT!J:J,MASTER_AR_REPORT!K:K,"Current"),0)
A13: 0-30 Days | B13: =COUNTIFS(MASTER_AR_REPORT!K:K,"0-30 Days",MASTER_AR_REPORT!I:I,">0") | C13: =SUMIFS(MASTER_AR_REPORT!I:I,MASTER_AR_REPORT!K:K,"0-30 Days") | D13: =IF(C$17=0,0,C13/C$17) | E13: =IFERROR(AVERAGEIFS(MASTER_AR_REPORT!J:J,MASTER_AR_REPORT!K:K,"0-30 Days"),0)
A14: 31-60 Days | B14: =COUNTIFS(MASTER_AR_REPORT!K:K,"31-60 Days",MASTER_AR_REPORT!I:I,">0") | C14: =SUMIFS(MASTER_AR_REPORT!I:I,MASTER_AR_REPORT!K:K,"31-60 Days") | D14: =IF(C$17=0,0,C14/C$17) | E14: =IFERROR(AVERAGEIFS(MASTER_AR_REPORT!J:J,MASTER_AR_REPORT!K:K,"31-60 Days"),0)
A15: 61-90 Days | B15: =COUNTIFS(MASTER_AR_REPORT!K:K,"61-90 Days",MASTER_AR_REPORT!I:I,">0") | C15: =SUMIFS(MASTER_AR_REPORT!I:I,MASTER_AR_REPORT!K:K,"61-90 Days") | D15: =IF(C$17=0,0,C15/C$17) | E15: =IFERROR(AVERAGEIFS(MASTER_AR_REPORT!J:J,MASTER_AR_REPORT!K:K,"61-90 Days"),0)
A16: 90+ Days | B16: =COUNTIFS(MASTER_AR_REPORT!K:K,"90+ Days",MASTER_AR_REPORT!I:I,">0") | C16: =SUMIFS(MASTER_AR_REPORT!I:I,MASTER_AR_REPORT!K:K,"90+ Days") | D16: =IF(C$17=0,0,C16/C$17) | E16: =IFERROR(AVERAGEIFS(MASTER_AR_REPORT!J:J,MASTER_AR_REPORT!K:K,"90+ Days"),0)
A17: TOTAL | B17: =SUM(B12:B16) | C17: =SUM(C12:C16) | D17: =SUM(D12:D16)
A19: COLLECTOR-WISE SUMMARY
A20: Collector | B20: Invoice Count | C20: Total Outstanding | D20: High Risk Amt | E20: Avg Days | F20: Collection % | G20: % of Total
A21: Watches | B21: =COUNTIFS(MASTER_AR_REPORT!B:B,"Watches",MASTER_AR_REPORT!I:I,">0") | C21: =SUMIFS(MASTER_AR_REPORT!I:I,MASTER_AR_REPORT!B:B,"Watches",MASTER_AR_REPORT!I:I,">0") | D21: =SUMIFS(MASTER_AR_REPORT!I:I,MASTER_AR_REPORT!B:B,"Watches",MASTER_AR_REPORT!L:L,"HIGH RISK") | E21: =IFERROR(AVERAGEIFS(MASTER_AR_REPORT!J:J,MASTER_AR_REPORT!B:B,"Watches",MASTER_AR_REPORT!I:I,">0"),0) | F21: =IF(SUMIFS(MASTER_AR_REPORT!F:F,MASTER_AR_REPORT!B:B,"Watches")=0,0,SUMIFS(MASTER_AR_REPORT!H:H,MASTER_AR_REPORT!B:B,"Watches")/SUMIFS(MASTER_AR_REPORT!F:F,MASTER_AR_REPORT!B:B,"Watches")) | G21: =IF(C$25=0,0,C21/C$25)
A22: Praveen | B22: =COUNTIFS(MASTER_AR_REPORT!B:B,"Praveen",MASTER_AR_REPORT!I:I,">0") | C22: =SUMIFS(MASTER_AR_REPORT!I:I,MASTER_AR_REPORT!B:B,"Praveen",MASTER_AR_REPORT!I:I,">0") | D22: =SUMIFS(MASTER_AR_REPORT!I:I,MASTER_AR_REPORT!B:B,"Praveen",MASTER_AR_REPORT!L:L,"HIGH RISK") | E22: =IFERROR(AVERAGEIFS(MASTER_AR_REPORT!J:J,MASTER_AR_REPORT!B:B,"Praveen",MASTER_AR_REPORT!I:I,">0"),0) | F22: =IF(SUMIFS(MASTER_AR_REPORT!F:F,MASTER_AR_REPORT!B:B,"Praveen")=0,0,SUMIFS(MASTER_AR_REPORT!H:H,MASTER_AR_REPORT!B:B,"Praveen")/SUMIFS(MASTER_AR_REPORT!F:F,MASTER_AR_REPORT!B:B,"Praveen")) | G22: =IF(C$25=0,0,C22/C$25)
A23: Mujahid | B23: =COUNTIFS(MASTER_AR_REPORT!B:B,"Mujahid",MASTER_AR_REPORT!I:I,">0") | C23: =SUMIFS(MASTER_AR_REPORT!I:I,MASTER_AR_REPORT!B:B,"Mujahid",MASTER_AR_REPORT!I:I,">0") | D23: =SUMIFS(MASTER_AR_REPORT!I:I,MASTER_AR_REPORT!B:B,"Mujahid",MASTER_AR_REPORT!L:L,"HIGH RISK") | E23: =IFERROR(AVERAGEIFS(MASTER_AR_REPORT!J:J,MASTER_AR_REPORT!B:B,"Mujahid",MASTER_AR_REPORT!I:I,">0"),0) | F23: =IF(SUMIFS(MASTER_AR_REPORT!F:F,MASTER_AR_REPORT!B:B,"Mujahid")=0,0,SUMIFS(MASTER_AR_REPORT!H:H,MASTER_AR_REPORT!B:B,"Mujahid")/SUMIFS(MASTER_AR_REPORT!F:F,MASTER_AR_REPORT!B:B,"Mujahid")) | G23: =IF(C$25=0,0,C23/C$25)
A24: Vinod | B24: =COUNTIFS(MASTER_AR_REPORT!B:B,"Vinod",MASTER_AR_REPORT!I:I,">0") | C24: =SUMIFS(MASTER_AR_REPORT!I:I,MASTER_AR_REPORT!B:B,"Vinod",MASTER_AR_REPORT!I:I,">0") | D24: =SUMIFS(MASTER_AR_REPORT!I:I,MASTER_AR_REPORT!B:B,"Vinod",MASTER_AR_REPORT!L:L,"HIGH RISK") | E24: =IFERROR(AVERAGEIFS(MASTER_AR_REPORT!J:J,MASTER_AR_REPORT!B:B,"Vinod",MASTER_AR_REPORT!I:I,">0"),0) | F24: =IF(SUMIFS(MASTER_AR_REPORT!F:F,MASTER_AR_REPORT!B:B,"Vinod")=0,0,SUMIFS(MASTER_AR_REPORT!H:H,MASTER_AR_REPORT!B:B,"Vinod")/SUMIFS(MASTER_AR_REPORT!F:F,MASTER_AR_REPORT!B:B,"Vinod")) | G24: =IF(C$25=0,0,C24/C$25)
A25: TOTAL | B25: =SUM(B21:B24) | C25: =SUM(C21:C24) | D25: =SUM(D21:D24) | E25: =SUM(E21:E24) | F25: =SUM(F21:F24) | G25: =SUM(G21:G24)
A27: DSO ACTIONS SUMMARY
A28: Reason | B28: Count | C28: Total Amount | D28: % of Total
A29: Send Dso | B29: =COUNTIFS('DSO Actions'!J:J,"*Send Dso*") | C29: =SUMIFS('DSO Actions'!F:F,'DSO Actions'!J:J,"*Send Dso*") | D29: =IF(SUM('DSO Actions'!F:F)=0,0,C29/SUM('DSO Actions'!F:F))
A30: Stock Return | B30: =COUNTIFS('DSO Actions'!J:J,"*Stock Return*") | C30: =SUMIFS('DSO Actions'!F:F,'DSO Actions'!J:J,"*Stock Return*") | D30: =IF(SUM('DSO Actions'!F:F)=0,0,C30/SUM('DSO Actions'!F:F))
A31: Credit Note | B31: =COUNTIFS('DSO Actions'!J:J,"*Credit Note*") | C31: =SUMIFS('DSO Actions'!F:F,'DSO Actions'!J:J,"*Credit Note*") | D31: =IF(SUM('DSO Actions'!F:F)=0,0,C31/SUM('DSO Actions'!F:F))
A32: TOTAL | B32: =SUM(B29:B31) | C32: =SUM(C29:C31) | D32: =SUM(D29:D31)
A34: CALLING LIST (Overdue > 30 Days)
A35: Risk Level | B35: Count | C35: Total Outstanding | D35: Avg Days Overdue
A36: HIGH RISK | B36: =COUNTIFS(MASTER_AR_REPORT!L:L,"HIGH RISK",MASTER_AR_REPORT!J:J,">=30") | C36: =SUMIFS(MASTER_AR_REPORT!I:I,MASTER_AR_REPORT!L:L,"HIGH RISK",MASTER_AR_REPORT!J:J,">=30") | D36: =IFERROR(AVERAGEIFS(MASTER_AR_REPORT!J:J,MASTER_AR_REPORT!L:L,"HIGH RISK",MASTER_AR_REPORT!J:J,">=30"),0)
A37: Medium | B37: =COUNTIFS(MASTER_AR_REPORT!L:L,"Medium",MASTER_AR_REPORT!J:J,">=30") | C37: =SUMIFS(MASTER_AR_REPORT!I:I,MASTER_AR_REPORT!L:L,"Medium",MASTER_AR_REPORT!J:J,">=30") | D37: =IFERROR(AVERAGEIFS(MASTER_AR_REPORT!J:J,MASTER_AR_REPORT!L:L,"Medium",MASTER_AR_REPORT!J:J,">=30"),0)
A38: Low-Medium | B38: =COUNTIFS(MASTER_AR_REPORT!L:L,"Low-Medium",MASTER_AR_REPORT!J:J,">=30") | C38: =SUMIFS(MASTER_AR_REPORT!I:I,MASTER_AR_REPORT!L:L,"Low-Medium",MASTER_AR_REPORT!J:J,">=30") | D38: =IFERROR(AVERAGEIFS(MASTER_AR_REPORT!J:J,MASTER_AR_REPORT!L:L,"Low-Medium",MASTER_AR_REPORT!J:J,">=30"),0)
A39: Low | B39: =COUNTIFS(MASTER_AR_REPORT!L:L,"Low",MASTER_AR_REPORT!J:J,">=30") | C39: =SUMIFS(MASTER_AR_REPORT!I:I,MASTER_AR_REPORT!L:L,"Low",MASTER_AR_REPORT!J:J,">=30") | D39: =IFERROR(AVERAGEIFS(MASTER_AR_REPORT!J:J,MASTER_AR_REPORT!L:L,"Low",MASTER_AR_REPORT!J:J,">=30"),0)
A40: TOTAL | B40: =SUM(B36:B39) | C40: =SUM(C36:C39) | D40: =SUM(D36:D39)
A42: DUE DATE PROXIMITY
A43: Due Period | B43: Invoice Count | C43: Total Amount
A44: Overdue (Past Due) | B44: =COUNTIFS(MASTER_AR_REPORT!J:J,">0",MASTER_AR_REPORT!I:I,">0") | C44: =SUMIFS(MASTER_AR_REPORT!I:I,MASTER_AR_REPORT!J:J,">0")
A45: Due This Week (next 0-7d) | B45: =COUNTIFS(MASTER_AR_REPORT!J:J,"<=0",MASTER_AR_REPORT!J:J,">=-7",MASTER_AR_REPORT!I:I,">0") | C45: =SUMIFS(MASTER_AR_REPORT!I:I,MASTER_AR_REPORT!J:J,"<=0",MASTER_AR_REPORT!J:J,">=-7")
A46: Due Next Week (8-14d) | B46: =COUNTIFS(MASTER_AR_REPORT!J:J,"<=-8",MASTER_AR_REPORT!J:J,">=-14",MASTER_AR_REPORT!I:I,">0") | C46: =SUMIFS(MASTER_AR_REPORT!I:I,MASTER_AR_REPORT!J:J,"<=-8",MASTER_AR_REPORT!J:J,">=-14")
A47: Due Next 30 Days (15-30d) | B47: =COUNTIFS(MASTER_AR_REPORT!J:J,"<=-15",MASTER_AR_REPORT!J:J,">=-30",MASTER_AR_REPORT!I:I,">0") | C47: =SUMIFS(MASTER_AR_REPORT!I:I,MASTER_AR_REPORT!J:J,"<=-15",MASTER_AR_REPORT!J:J,">=-30")
...

Sheet MASTER_AR_REPORT
A1: S.No | B1: Source Sheet | C1: Date | D1: Invoice No | E1: Customer Name | F1: Invoice Amount | G1: Due Date | H1: Paid Amount | I1: Outstanding Amount | J1: Days Overdue | K1: Aging Bucket | L1: Risk Level | M1: Follow-up Priority | N1: Call Status
A2: 1 | B2: Watches | C2: 46144 | D2: SLGCW/46/26-27 | E2: C. Ramchander Watch Co. | F2: 1400 | G2: 46144 | H2: 0 | I2: =MAX(0,F2-H2) | J2: =IF(G2="",0,MAX(0,TODAY()-G2)) | K2: =IF(I2<=0,"Current",IF(J2<=30,"0-30 Days",IF(J2<=60,"31-60 Days",IF(J2<=90,"61-90 Days","90+ Days")))) | L2: =IF(I2<=0,"-",IF(J2<=30,"Low",IF(J2<=60,"Low-Medium",IF(J2<=90,"Medium","HIGH RISK")))) | M2: We need to give Credit Note | N2: Pending
A3: 2 | B3: Watches | C3: 45716 | D3: SLGCW/1077/24-25 | E3: KHALEEL WATCH CO. | F3: 159.67 | G3: 45716 | H3: 0 | I3: =MAX(0,F3-H3) | J3: =IF(G3="",0,MAX(0,TODAY()-G3)) | K3: =IF(I3<=0,"Current",IF(J3<=30,"0-30 Days",IF(J3<=60,"31-60 Days",IF(J3<=90,"61-90 Days","90+ Days")))) | L3: =IF(I3<=0,"-",IF(J3<=30,"Low",IF(J3<=60,"Low-Medium",IF(J3<=90,"Medium","HIGH RISK")))) | M3: Sponge Not recived - Send DSO | N3: Pending
A4: 3 | B4: Watches | C4: 46013 | D4: SLGCW/1035/25-26 | E4: KHALEEL WATCH CO. | F4: 383 | G4: 46043 | H4: 383 | I4: =MAX(0,F4-H4) | J4: =IF(G4="",0,MAX(0,TODAY()-G4)) | K4: =IF(I4<=0,"Current",IF(J4<=30,"0-30 Days",IF(J4<=60,"31-60 Days",IF(J4<=90,"61-90 Days","90+ Days")))) | L4: =IF(I4<=0,"-",IF(J4<=30,"Low",IF(J4<=60,"Low-Medium",IF(J4<=90,"Medium","HIGH RISK")))) | M4: Paid Online | N4: Pending
A5: 4 | B5: Watches | C5: 45996 | D5: SLGCW/969/25-26 | E5: KISHORE WATCH CO | F5: 2852 | G5: 46041 | H5: 0 | I5: =MAX(0,F5-H5) | J5: =IF(G5="",0,MAX(0,TODAY()-G5)) | K5: =IF(I5<=0,"Current",IF(J5<=30,"0-30 Days",IF(J5<=60,"31-60 Days",IF(J5<=90,"61-90 Days","90+ Days")))) | L5: =IF(I5<=0,"-",IF(J5<=30,"Low",IF(J5<=60,"Low-Medium",IF(J5<=90,"Medium","HIGH RISK")))) | M5: Bill not available | N5: Pending
A6: 5 | B6: Watches | C6: 46139 | D6: SLGCW/25/26-27 | E6: KISHORE WATCH CO | F6: 196667 | G6: 46184 | H6: 0 | I6: =MAX(0,F6-H6) | J6: =IF(G6="",0,MAX(0,TODAY()-G6)) | K6: =IF(I6<=0,"Current",IF(J6<=30,"0-30 Days",IF(J6<=60,"31-60 Days",IF(J6<=90,"61-90 Days","90+ Days")))) | L6: =IF(I6<=0,"-",IF(J6<=30,"Low",IF(J6<=60,"Low-Medium",IF(J6<=90,"Medium","HIGH RISK")))) | N6: Pending
A7: 6 | B7: Watches | C7: 46144 | D7: SLGCW/51/26-27 | E7: KISHORE WATCH CO | F7: 9035 | G7: 46189 | H7: 0 | I7: =MAX(0,F7-H7) | J7: =IF(G7="",0,MAX(0,TODAY()-G7)) | K7: =IF(I7<=0,"Current",IF(J7<=30,"0-30 Days",IF(J7<=60,"31-60 Days",IF(J7<=90,"61-90 Days","90+ Days")))) | L7: =IF(I7<=0,"-",IF(J7<=30,"Low",IF(J7<=60,"Low-Medium",IF(J7<=90,"Medium","HIGH RISK")))) | N7: Pending
A8: 7 | B8: Watches | C8: 46148 | D8: SLGCW/59/26-27 | E8: KISHORE WATCH CO | F8: 19731 | G8: 46193 | H8: 0 | I8: =MAX(0,F8-H8) | J8: =IF(G8="",0,MAX(0,TODAY()-G8)) | K8: =IF(I8<=0,"Current",IF(J8<=30,"0-30 Days",IF(J8<=60,"31-60 Days",IF(J8<=90,"61-90 Days","90+ Days")))) | L8: =IF(I8<=0,"-",IF(J8<=30,"Low",IF(J8<=60,"Low-Medium",IF(J8<=90,"Medium","HIGH RISK")))) | N8: Pending
A9: 8 | B9: Watches | C9: 46136 | D9: SLGCW/15/26-27 | E9: Maruti watche & electronics | F9: 13163 | G9: 46181 | H9: 0 | I9: =MAX(0,F9-H9) | J9: =IF(G9="",0,MAX(0,TODAY()-G9)) | K9: =IF(I9<=0,"Current",IF(J9<=30,"0-30 Days",IF(J9<=60,"31-60 Days",IF(J9<=90,"61-90 Days","90+ Days")))) | L9: =IF(I9<=0,"-",IF(J9<=30,"Low",IF(J9<=60,"Low-Medium",IF(J9<=90,"Medium","HIGH RISK")))) | N9: Pending
A10: 9 | B10: Watches | C10: 46142 | D10: SLGCW/40/26-27 | E10: Maruti watche & electronics | F10: 48979 | G10: 46187 | H10: 0 | I10: =MAX(0,F10-H10) | J10: =IF(G10="",0,MAX(0,TODAY()-G10)) | K10: =IF(I10<=0,"Current",IF(J10<=30,"0-30 Days",IF(J10<=60,"31-60 Days",IF(J10<=90,"61-90 Days","90+ Days")))) | L10: =IF(I10<=0,"-",IF(J10<=30,"Low",IF(J10<=60,"Low-Medium",IF(J10<=90,"Medium","HIGH RISK")))) | N10: Pending
A11: 10 | B11: Watches | C11: 46144 | D11: SLGCW/53/26-27 | E11: Maruti watche & electronics | F11: 22969 | G11: 46189 | H11: 0 | I11: =MAX(0,F11-H11) | J11: =IF(G11="",0,MAX(0,TODAY()-G11)) | K11: =IF(I11<=0,"Current",IF(J11<=30,"0-30 Days",IF(J11<=60,"31-60 Days",IF(J11<=90,"61-90 Days","90+ Days")))) | L11: =IF(I11<=0,"-",IF(J11<=30,"Low",IF(J11<=60,"Low-Medium",IF(J11<=90,"Medium","HIGH RISK")))) | N11: Pending
A12: 11 | B12: Watches | C12: 46149 | D12: SLGCW/61/26-27 | E12: Maruti watche & electronics | F12: 14355 | G12: 46150 | H12: 0 | I12: =MAX(0,F12-H12) | J12: =IF(G12="",0,MAX(0,TODAY()-G12)) | K12: =IF(I12<=0,"Current",IF(J12<=30,"0-30 Days",IF(J12<=60,"31-60 Days",IF(J12<=90,"61-90 Days","90+ Days")))) | L12: =IF(I12<=0,"-",IF(J12<=30,"Low",IF(J12<=60,"Low-Medium",IF(J12<=90,"Medium","HIGH RISK")))) | M12: Number Busy | N12: Pending
A13: 12 | B13: Watches | C13: 46157 | D13: SLGCW/65/26-27 | E13: Maruti watche & electronics | F13: 3281 | G13: 46158 | H13: 0 | I13: =MAX(0,F13-H13) | J13: =IF(G13="",0,MAX(0,TODAY()-G13)) | K13: =IF(I13<=0,"Current",IF(J13<=30,"0-30 Days",IF(J13<=60,"31-60 Days",IF(J13<=90,"61-90 Days","90+ Days")))) | L13: =IF(I13<=0,"-",IF(J13<=30,"Low",IF(J13<=60,"Low-Medium",IF(J13<=90,"Medium","HIGH RISK")))) | M13: Number Busy | N13: Pending
A14: 13 | B14: Watches | C14: 46158 | D14: SLGCW/67/26-27 | E14: Maruti watche & electronics | F14: 8756 | G14: 46159 | H14: 0 | I14: =MAX(0,F14-H14) | J14: =IF(G14="",0,MAX(0,TODAY()-G14)) | K14: =IF(I14<=0,"Current",IF(J14<=30,"0-30 Days",IF(J14<=60,"31-60 Days",IF(J14<=90,"61-90 Days","90+ Days")))) | L14: =IF(I14<=0,"-",IF(J14<=30,"Low",IF(J14<=60,"Low-Medium",IF(J14<=90,"Medium","HIGH RISK")))) | M14: Number Busy | N14: Pending
A15: 14 | B15: Watches | C15: 45705 | D15: SLGCW/1043/24-25 | E15: MILAP GENERAL STORES | F15: 560 | G15: 45705 | H15: 0 | I15: =MAX(0,F15-H15) | J15: =IF(G15="",0,MAX(0,TODAY()-G15)) | K15: =IF(I15<=0,"Current",IF(J15<=30,"0-30 Days",IF(J15<=60,"31-60 Days",IF(J15<=90,"61-90 Days","90+ Days")))) | L15: =IF(I15<=0,"-",IF(J15<=30,"Low",IF(J15<=60,"Low-Medium",IF(J15<=90,"Medium","HIGH RISK")))) | M15: Not Lifting Call | N15: Pending
A16: 15 | B16: Watches | C16: 45708 | D16: SLGCW/1061/24-25 | E16: MILAP GENERAL STORES | F16: 103.36 | G16: 45708 | H16: 0 | I16: =MAX(0,F16-H16) | J16: =IF(G16="",0,MAX(0,TODAY()-G16)) | K16: =IF(I16<=0,"Current",IF(J16<=30,"0-30 Days",IF(J16<=60,"31-60 Days",IF(J16<=90,"61-90 Days","90+ Days")))) | L16: =IF(I16<=0,"-",IF(J16<=30,"Low",IF(J16<=60,"Low-Medium",IF(J16<=90,"Medium","HIGH RISK")))) | M16: Not Lifting Call | N16: Pending
A17: 16 | B17: Watches | C17: 46144 | D17: SLGCW/58/26-27 | E17: NAZEER & SONS | F17: 14781 | G17: 46174 | H17: 0 | I17: =MAX(0,F17-H17) | J17: =IF(G17="",0,MAX(0,TODAY()-G17)) | K17: =IF(I17<=0,"Current",IF(J17<=30,"0-30 Days",IF(J17<=60,"31-60 Days",IF(J17<=90,"61-90 Days","90+ Days")))) | L17: =IF(I17<=0,"-",IF(J17<=30,"Low",IF(J17<=60,"Low-Medium",IF(J17<=90,"Medium","HIGH RISK")))) | N17: Pending
A18: 17 | B18: Watches | C18: 46150 | D18: SLGCW/62/26-27 | E18: NAZEER & SONS | F18: 12783 | G18: 46151 | H18: 12783 | I18: =MAX(0,F18-H18) | J18: =IF(G18="",0,MAX(0,TODAY()-G18)) | K18: =IF(I18<=0,"Current",IF(J18<=30,"0-30 Days",IF(J18<=60,"31-60 Days",IF(J18<=90,"61-90 Days","90+ Days")))) | L18: =IF(I18<=0,"-",IF(J18<=30,"Low",IF(J18<=60,"Low-Medium",IF(J18<=90,"Medium","HIGH RISK")))) | M18: Customer says Cheque already Paid | N18: Pending
A19: 18 | B19: Watches | C19: 45667 | D19: SLGCW/898/24-25 | E19: RAMESH WATCH CO PVT LTD K-INORBIT | F19: 92000 | G19: 45667 | H19: 0 | I19: =MAX(0,F19-H19) | J19: =IF(G19="",0,MAX(0,TODAY()-G19)) | K19: =IF(I19<=0,"Current",IF(J19<=30,"0-30 Days",IF(J19<=60,"31-60 Days",IF(J19<=90,"61-90 Days","90+ Days")))) | L19: =IF(I19<=0,"-",IF(J19<=30,"Low",IF(J19<=60,"Low-Medium",IF(J19<=90,"Medium","HIGH RISK")))) | M19: Issue | N19: Pending
A20: 19 | B20: Watches | C20: 46044 | D20: SLGCW/1138/25-26 | E20: RAMESH WATCH CO PVT LTD K-INORBIT | F20: 74393 | G20: 46089 | H20: 0 | I20: =MAX(0,F20-H20) | J20: =IF(G20="",0,MAX(0,TODAY()-G20)) | K20: =IF(I20<=0,"Current",IF(J20<=30,"0-30 Days",IF(J20<=60,"31-60 Days",IF(J20<=90,"61-90 Days","90+ Days")))) | L20: =IF(I20<=0,"-",IF(J20<=30,"Low",IF(J20<=60,"Low-Medium",IF(J20<=90,"Medium","HIGH RISK")))) | M20: DSO will collect | N20: Pending
A21: 20 | B21: Watches | C21: 46045 | D21: SLGCW/1150/25-26 | E21: RAMESH WATCH CO PVT LTD K-INORBIT | F21: 263334 | G21: 46090 | H21: 0 | I21: =MAX(0,F21-H21) | J21: =IF(G21="",0,MAX(0,TODAY()-G21)) | K21: =IF(I21<=0,"Current",IF(J21<=30,"0-30 Days",IF(J21<=60,"31-60 Days",IF(J21<=90,"61-90 Days","90+ Days")))) | L21: =IF(I21<=0,"-",IF(J21<=30,"Low",IF(J21<=60,"Low-Medium",IF(J21<=90,"Medium","HIGH RISK")))) | M21: DSO will collect | N21: Pending
A22: 21 | B22: Watches | C22: 46045 | D22: SLGCW/1147/25-26 | E22: RAMESH WATCH CO PVT LTD K-INORBIT | F22: 60364 | G22: 46090 | H22: 0 | I22: =MAX(0,F22-H22) | J22: =IF(G22="",0,MAX(0,TODAY()-G22)) | K22: =IF(I22<=0,"Current",IF(J22<=30,"0-30 Days",IF(J22<=60,"31-60 Days",IF(J22<=90,"61-90 Days","90+ Days")))) | L22: =IF(I22<=0,"-",IF(J22<=30,"Low",IF(J22<=60,"Low-Medium",IF(J22<=90,"Medium","HIGH RISK")))) | M22: DSO will collect | N22: Pending
A23: 22 | B23: Watches | C23: 46045 | D23: SLGCW/1149/25-26 | E23: RAMESH WATCH CO PVT LTD K-INORBIT | F23: 30132 | G23: 46090 | H23: 0 | I23: =MAX(0,F23-H23) | J23: =IF(G23="",0,MAX(0,TODAY()-G23)) | K23: =IF(I23<=0,"Current",IF(J23<=30,"0-30 Days",IF(J23<=60,"31-60 Days",IF(J23<=90,"61-90 Days","90+ Days")))) | L23: =IF(I23<=0,"-",IF(J23<=30,"Low",IF(J23<=60,"Low-Medium",IF(J23<=90,"Medium","HIGH RISK")))) | M23: DSO will collect | N23: Pending
A24: 23 | B24: Watches | C24: 46055 | D24: SLGCW/1188/25-26 | E24: RAMESH WATCH CO PVT LTD K-INORBIT | F24: 304908 | G24: 46100 | H24: 0 | I24: =MAX(0,F24-H24) | J24: =IF(G24="",0,MAX(0,TODAY()-G24)) | K24: =IF(I24<=0,"Current",IF(J24<=30,"0-30 Days",IF(J24<=60,"31-60 Days",IF(J24<=90,"61-90 Days","90+ Days")))) | L24: =IF(I24<=0,"-",IF(J24<=30,"Low",IF(J24<=60,"Low-Medium",IF(J24<=90,"Medium","HIGH RISK")))) | M24: DSO will collect | N24: Pending
A25: 24 | B25: Watches | C25: 46067 | D25: SLGCW/1226/25-26 | E25: RAMESH WATCH CO PVT LTD K-INORBIT | F25: 51332 | G25: 46112 | H25: 0 | I25: =MAX(0,F25-H25) | J25: =IF(G25="",0,MAX(0,TODAY()-G25)) | K25: =IF(I25<=0,"Current",IF(J25<=30,"0-30 Days",IF(J25<=60,"31-60 Days",IF(J25<=90,"61-90 Days","90+ Days")))) | L25: =IF(I25<=0,"-",IF(J25<=30,"Low",IF(J25<=60,"Low-Medium",IF(J25<=90,"Medium","HIGH RISK")))) | M25: DSO will collect | N25: Pending
A26: 25 | B26: Watches | C26: 46076 | D26: SLGCW/1233/25-26 | E26: RAMESH WATCH CO PVT LTD K-INORBIT | F26: 11979 | G26: 46121 | H26: 0 | I26: =MAX(0,F26-H26) | J26: =IF(G26="",0,MAX(0,TODAY()-G26)) | K26: =IF(I26<=0,"Current",IF(J26<=30,"0-30 Days",IF(J26<=60,"31-60 Days",IF(J26<=90,"61-90 Days","90+ Days")))) | L26: =IF(I26<=0,"-",IF(J26<=30,"Low",IF(J26<=60,"Low-Medium",IF(J26<=90,"Medium","HIGH RISK")))) | M26: DSO will collect | N26: Pending
A27: 26 | B27: Watches | C27: 46076 | D27: SLGCW/1235/25-26 | E27: RAMESH WATCH CO PVT LTD K-INORBIT | F27: 6291 | G27: 46121 | H27: 0 | I27: =MAX(0,F27-H27) | J27: =IF(G27="",0,MAX(0,TODAY()-G27)) | K27: =IF(I27<=0,"Current",IF(J27<=30,"0-30 Days",IF(J27<=60,"31-60 Days",IF(J27<=90,"61-90 Days","90+ Days")))) | L27: =IF(I27<=0,"-",IF(J27<=30,"Low",IF(J27<=60,"Low-Medium",IF(J27<=90,"Medium","HIGH RISK")))) | M27: DSO will collect | N27: Pending
A28: 27 | B28: Watches | C28: 46076 | D28: SLGCW/1236/25-26 | E28: RAMESH WATCH CO PVT LTD K-INORBIT | F28: 7296 | G28: 46121 | H28: 0 | I28: =MAX(0,F28-H28) | J28: =IF(G28="",0,MAX(0,TODAY()-G28)) | K28: =IF(I28<=0,"Current",IF(J28<=30,"0-30 Days",IF(J28<=60,"31-60 Days",IF(J28<=90,"61-90 Days","90+ Days")))) | L28: =IF(I28<=0,"-",IF(J28<=30,"Low",IF(J28<=60,"Low-Medium",IF(J28<=90,"Medium","HIGH RISK")))) | M28: DSO will collect | N28: Pending
A29: 28 | B29: Watches | C29: 46090 | D29: SLGCW/1247/25-26 | E29: RAMESH WATCH CO PVT LTD K-INORBIT | F29: 17417 | G29: 46135 | H29: 0 | I29: =MAX(0,F29-H29) | J29: =IF(G29="",0,MAX(0,TODAY()-G29)) | K29: =IF(I29<=0,"Current",IF(J29<=30,"0-30 Days",IF(J29<=60,"31-60 Days",IF(J29<=90,"61-90 Days","90+ Days")))) | L29: =IF(I29<=0,"-",IF(J29<=30,"Low",IF(J29<=60,"Low-Medium",IF(J29<=90,"Medium","HIGH RISK")))) | M29: DSO will collect | N29: Pending
... A54: 53 | B54: Watches | C54: 46142 | D54: SLGCW/41/26-27 | E54: Siddi Times & Electronics | F54: 149682 | G54: 46143 | H54: 0 | I54: =MAX(0,F54-H54) | J54: =IF(G54="",0,MAX(0,TODAY()-G54)) | K54: =IF(I54<=0,"Current",IF(J54<=30,"0-30 Days",IF(J54<=60,"31-60 Days",IF(J54<=90,"61-90 Days","90+ Days")))) | L54: =IF(I54<=0,"-",IF(J54<=30,"Low",IF(J54<=60,"Low-Medium",IF(J54<=90,"Medium","HIGH RISK")))) | M54: Paid by Cheque | N54: Pending
A55: 54 | B55: Watches | C55: 46102 | D55: SLGCW/1263/25-26 | E55: SS WATCHES AND SUNGLASSES | F55: 12806 | G55: 46102 | H55: 0 | I55: =MAX(0,F55-H55) | J55: =IF(G55="",0,MAX(0,TODAY()-G55)) | K55: =IF(I55<=0,"Current",IF(J55<=30,"0-30 Days",IF(J55<=60,"31-60 Days",IF(J55<=90,"61-90 Days","90+ Days")))) | L55: =IF(I55<=0,"-",IF(J55<=30,"Low",IF(J55<=60,"Low-Medium",IF(J55<=90,"Medium","HIGH RISK")))) | N55: Pending
A56: 55 | B56: Watches | C56: 46137 | D56: SLGCW/18/26-27 | E56: Sunny Watch | F56: 111599 | G56: 46138 | H56: 0 | I56: =MAX(0,F56-H56) | J56: =IF(G56="",0,MAX(0,TODAY()-G56)) | K56: =IF(I56<=0,"Current",IF(J56<=30,"0-30 Days",IF(J56<=60,"31-60 Days",IF(J56<=90,"61-90 Days","90+ Days")))) | L56: =IF(I56<=0,"-",IF(J56<=30,"Low",IF(J56<=60,"Low-Medium",IF(J56<=90,"Medium","HIGH RISK")))) | M56: =I79 | N56: Pending
A57: 56 | B57: Watches | C57: 46144 | D57: SLGCW/56/26-27 | E57: Sunny Watch | F57: 20227 | G57: 46169 | H57: 0 | I57: =MAX(0,F57-H57) | J57: =IF(G57="",0,MAX(0,TODAY()-G57)) | K57: =IF(I57<=0,"Current",IF(J57<=30,"0-30 Days",IF(J57<=60,"31-60 Days",IF(J57<=90,"61-90 Days","90+ Days")))) | L57: =IF(I57<=0,"-",IF(J57<=30,"Low",IF(J57<=60,"Low-Medium",IF(J57<=90,"Medium","HIGH RISK")))) | N57: Pending
A58: 57 | B58: Watches | C58: 46137 | D58: SLGCW/20/26-27 | E58: THE TIMES | F58: 70357 | G58: 46137 | H58: 0 | I58: =MAX(0,F58-H58) | J58: =IF(G58="",0,MAX(0,TODAY()-G58)) | K58: =IF(I58<=0,"Current",IF(J58<=30,"0-30 Days",IF(J58<=60,"31-60 Days",IF(J58<=90,"61-90 Days","90+ Days")))) | L58: =IF(I58<=0,"-",IF(J58<=30,"Low",IF(J58<=60,"Low-Medium",IF(J58<=90,"Medium","HIGH RISK")))) | M58: Paid by Cheque | N58: Pending
A59: 58 | B59: Watches | C59: 2026-05-19 | D59: SLGCW/70/26-27 | E59: CENTRAL WATCH CO. | F59: 35496 | G59: 2026-05-20 | H59: 0 | I59: =MAX(0,F59-H59) | J59: =IF(G59="",0,MAX(0,TODAY()-G59)) | K59: =IF(I59<=0,"Current",IF(J59<=30,"0-30 Days",IF(J59<=60,"31-60 Days",IF(J59<=90,"61-90 Days","90+ Days")))) | L59: =IF(I59<=0,"-",IF(J59<=30,"Low",IF(J59<=60,"Low-Medium",IF(J59<=90,"Medium","HIGH RISK")))) | N59: Pending
A60: 59 | B60: Watches | C60: 2026-01-30 | D60: SLGCW/1177/25-26 | E60: COUNTER SALE | F60: 61596 | G60: 2026-01-31 | H60: 0 | I60: =MAX(0,F60-H60) | J60: =IF(G60="",0,MAX(0,TODAY()-G60)) | K60: =IF(I60<=0,"Current",IF(J60<=30,"0-30 Days",IF(J60<=60,"31-60 Days",IF(J60<=90,"61-90 Days","90+ Days")))) | L60: =IF(I60<=0,"-",IF(J60<=30,"Low",IF(J60<=60,"Low-Medium",IF(J60<=90,"Medium","HIGH RISK")))) | N60: Pending
A61: 60 | B61: Watches | C61: 2026-02-05 | D61: SLGCW/1193/25-26 | E61: COUNTER SALE | F61: 5996 | G61: 2026-02-06 | H61: 0 | I61: =MAX(0,F61-H61) | J61: =IF(G61="",0,MAX(0,TODAY()-G61)) | K61: =IF(I61<=0,"Current",IF(J61<=30,"0-30 Days",IF(J61<=60,"31-60 Days",IF(J61<=90,"61-90 Days","90+ Days")))) | L61: =IF(I61<=0,"-",IF(J61<=30,"Low",IF(J61<=60,"Low-Medium",IF(J61<=90,"Medium","HIGH RISK")))) | N61: Pending
A62: 61 | B62: Watches | C62: 2026-05-02 | D62: SLGCW/47/26-27 | E62: COUNTER SALE | F62: 4496 | G62: 2026-05-03 | H62: 0 | I62: =MAX(0,F62-H62) | J62: =IF(G62="",0,MAX(0,TODAY()-G62)) | K62: =IF(I62<=0,"Current",IF(J62<=30,"0-30 Days",IF(J62<=60,"31-60 Days",IF(J62<=90,"61-90 Days","90+ Days")))) | L62: =IF(I62<=0,"-",IF(J62<=30,"Low",IF(J62<=60,"Low-Medium",IF(J62<=90,"Medium","HIGH RISK")))) | N62: Pending
A63: 62 | B63: Watches | C63: 2026-05-02 | D63: SLGCW/48/26-27 | E63: COUNTER SALE | F63: 3371 | G63: 2026-05-03 | H63: 0 | I63: =MAX(0,F63-H63) | J63: =IF(G63="",0,MAX(0,TODAY()-G63)) | K63: =IF(I63<=0,"Current",IF(J63<=30,"0-30 Days",IF(J63<=60,"31-60 Days",IF(J63<=90,"61-90 Days","90+ Days")))) | L63: =IF(I63<=0,"-",IF(J63<=30,"Low",IF(J63<=60,"Low-Medium",IF(J63<=90,"Medium","HIGH RISK")))) | N63: Pending
A64: 63 | B64: Watches | C64: 2026-05-11 | D64: SLGCW/63/26-27 | E64: COUNTER SALE | F64: 2922 | G64: 2026-05-12 | H64: 0 | I64: =MAX(0,F64-H64) | J64: =IF(G64="",0,MAX(0,TODAY()-G64)) | K64: =IF(I64<=0,"Current",IF(J64<=30,"0-30 Days",IF(J64<=60,"31-60 Days",IF(J64<=90,"61-90 Days","90+ Days")))) | L64: =IF(I64<=0,"-",IF(J64<=30,"Low",IF(J64<=60,"Low-Medium",IF(J64<=90,"Medium","HIGH RISK")))) | N64: Pending
...

Sheet CALLING_LIST
A1: Collection Calling List (Overdue > 30 Days)
A2: Generated: 25-May-2026 | Total: 162 entries
A4: S.No | B4: Customer Name | C4: Invoice No | D4: Invoice Date | E4: Due Date | F4: Outstanding Amount | G4: Days Overdue | H4: Aging Bucket | I4: Risk Level | J4: Previous Remarks | K4: Call Status
A5: 1 | B5: =MASTER_AR_REPORT!E3 | C5: =MASTER_AR_REPORT!D3 | D5: =MASTER_AR_REPORT!C3 | E5: =MASTER_AR_REPORT!G3 | F5: =MASTER_AR_REPORT!I3 | G5: =MASTER_AR_REPORT!J3 | H5: =MASTER_AR_REPORT!K3 | I5: =MASTER_AR_REPORT!L3 | J5: =MASTER_AR_REPORT!M3 | K5: Pending
A6: 2 | B6: =MASTER_AR_REPORT!E5 | C6: =MASTER_AR_REPORT!D5 | D6: =MASTER_AR_REPORT!C5 | E6: =MASTER_AR_REPORT!G5 | F6: =MASTER_AR_REPORT!I5 | G6: =MASTER_AR_REPORT!J5 | H6: =MASTER_AR_REPORT!K5 | I6: =MASTER_AR_REPORT!L5 | J6: =MASTER_AR_REPORT!M5 | K6: Pending
A7: 3 | B7: =MASTER_AR_REPORT!E15 | C7: =MASTER_AR_REPORT!D15 | D7: =MASTER_AR_REPORT!C15 | E7: =MASTER_AR_REPORT!G15 | F7: =MASTER_AR_REPORT!I15 | G7: =MASTER_AR_REPORT!J15 | H7: =MASTER_AR_REPORT!K15 | I7: =MASTER_AR_REPORT!L15 | J7: =MASTER_AR_REPORT!M15 | K7: Pending
A8: 4 | B8: =MASTER_AR_REPORT!E16 | C8: =MASTER_AR_REPORT!D16 | D8: =MASTER_AR_REPORT!C16 | E8: =MASTER_AR_REPORT!G16 | F8: =MASTER_AR_REPORT!I16 | G8: =MASTER_AR_REPORT!J16 | H8: =MASTER_AR_REPORT!K16 | I8: =MASTER_AR_REPORT!L16 | J8: =MASTER_AR_REPORT!M16 | K8: Pending
A9: 5 | B9: =MASTER_AR_REPORT!E19 | C9: =MASTER_AR_REPORT!D19 | D9: =MASTER_AR_REPORT!C19 | E9: =MASTER_AR_REPORT!G19 | F9: =MASTER_AR_REPORT!I19 | G9: =MASTER_AR_REPORT!J19 | H9: =MASTER_AR_REPORT!K19 | I9: =MASTER_AR_REPORT!L19 | J9: =MASTER_AR_REPORT!M19 | K9: Pending
A10: 6 | B10: =MASTER_AR_REPORT!E20 | C10: =MASTER_AR_REPORT!D20 | D10: =MASTER_AR_REPORT!C20 | E10: =MASTER_AR_REPORT!G20 | F10: =MASTER_AR_REPORT!I20 | G10: =MASTER_AR_REPORT!J20 | H10: =MASTER_AR_REPORT!K20 | I10: =MASTER_AR_REPORT!L20 | J10: =MASTER_AR_REPORT!M20 | K10: Pending
A11: 7 | B11: =MASTER_AR_REPORT!E21 | C11: =MASTER_AR_REPORT!D21 | D11: =MASTER_AR_REPORT!C21 | E11: =MASTER_AR_REPORT!G21 | F11: =MASTER_AR_REPORT!I21 | G11: =MASTER_AR_REPORT!J21 | H11: =MASTER_AR_REPORT!K21 | I11: =MASTER_AR_REPORT!L21 | J11: =MASTER_AR_REPORT!M21 | K11: Pending
A12: 8 | B12: =MASTER_AR_REPORT!E22 | C12: =MASTER_AR_REPORT!D22 | D12: =MASTER_AR_REPORT!C22 | E12: =MASTER_AR_REPORT!G22 | F12: =MASTER_AR_REPORT!I22 | G12: =MASTER_AR_REPORT!J22 | H12: =MASTER_AR_REPORT!K22 | I12: =MASTER_AR_REPORT!L22 | J12: =MASTER_AR_REPORT!M22 | K12: Pending
A13: 9 | B13: =MASTER_AR_REPORT!E23 | C13: =MASTER_AR_REPORT!D23 | D13: =MASTER_AR_REPORT!C23 | E13: =MASTER_AR_REPORT!G23 | F13: =MASTER_AR_REPORT!I23 | G13: =MASTER_AR_REPORT!J23 | H13: =MASTER_AR_REPORT!K23 | I13: =MASTER_AR_REPORT!L23 | J13: =MASTER_AR_REPORT!M23 | K13: Pending
A14: 10 | B14: =MASTER_AR_REPORT!E24 | C14: =MASTER_AR_REPORT!D24 | D14: =MASTER_AR_REPORT!C24 | E14: =MASTER_AR_REPORT!G24 | F14: =MASTER_AR_REPORT!I24 | G14: =MASTER_AR_REPORT!J24 | H14: =MASTER_AR_REPORT!K24 | I14: =MASTER_AR_REPORT!L24 | J14: =MASTER_AR_REPORT!M24 | K14: Pending
A15: 11 | B15: =MASTER_AR_REPORT!E25 | C15: =MASTER_AR_REPORT!D25 | D15: =MASTER_AR_REPORT!C25 | E15: =MASTER_AR_REPORT!G25 | F15: =MASTER_AR_REPORT!I25 | G15: =MASTER_AR_REPORT!J25 | H15: =MASTER_AR_REPORT!K25 | I15: =MASTER_AR_REPORT!L25 | J15: =MASTER_AR_REPORT!M25 | K15: Pending
A16: 12 | B16: =MASTER_AR_REPORT!E26 | C16: =MASTER_AR_REPORT!D26 | D16: =MASTER_AR_REPORT!C26 | E16: =MASTER_AR_REPORT!G26 | F16: =MASTER_AR_REPORT!I26 | G16: =MASTER_AR_REPORT!J26 | H16: =MASTER_AR_REPORT!K26 | I16: =MASTER_AR_REPORT!L26 | J16: =MASTER_AR_REPORT!M26 | K16: Pending
A17: 13 | B17: =MASTER_AR_REPORT!E27 | C17: =MASTER_AR_REPORT!D27 | D17: =MASTER_AR_REPORT!C27 | E17: =MASTER_AR_REPORT!G27 | F17: =MASTER_AR_REPORT!I27 | G17: =MASTER_AR_REPORT!J27 | H17: =MASTER_AR_REPORT!K27 | I17: =MASTER_AR_REPORT!L27 | J17: =MASTER_AR_REPORT!M27 | K17: Pending
A18: 14 | B18: =MASTER_AR_REPORT!E28 | C18: =MASTER_AR_REPORT!D28 | D18: =MASTER_AR_REPORT!C28 | E18: =MASTER_AR_REPORT!G28 | F18: =MASTER_AR_REPORT!I28 | G18: =MASTER_AR_REPORT!J28 | H18: =MASTER_AR_REPORT!K28 | I18: =MASTER_AR_REPORT!L28 | J18: =MASTER_AR_REPORT!M28 | K18: Pending
A19: 15 | B19: =MASTER_AR_REPORT!E29 | C19: =MASTER_AR_REPORT!D29 | D19: =MASTER_AR_REPORT!C29 | E19: =MASTER_AR_REPORT!G29 | F19: =MASTER_AR_REPORT!I29 | G19: =MASTER_AR_REPORT!J29 | H19: =MASTER_AR_REPORT!K29 | I19: =MASTER_AR_REPORT!L29 | J19: =MASTER_AR_REPORT!M29 | K19: Pending
A20: 16 | B20: =MASTER_AR_REPORT!E52 | C20: =MASTER_AR_REPORT!D52 | D20: =MASTER_AR_REPORT!C52 | E20: =MASTER_AR_REPORT!G52 | F20: =MASTER_AR_REPORT!I52 | G20: =MASTER_AR_REPORT!J52 | H20: =MASTER_AR_REPORT!K52 | I20: =MASTER_AR_REPORT!L52 | J20: =MASTER_AR_REPORT!M52 | K20: Pending
A21: 17 | B21: =MASTER_AR_REPORT!E53 | C21: =MASTER_AR_REPORT!D53 | D21: =MASTER_AR_REPORT!C53 | E21: =MASTER_AR_REPORT!G53 | F21: =MASTER_AR_REPORT!I53 | G21: =MASTER_AR_REPORT!J53 | H21: =MASTER_AR_REPORT!K53 | I21: =MASTER_AR_REPORT!L53 | J21: =MASTER_AR_REPORT!M53 | K21: Pending
A22: 18 | B22: =MASTER_AR_REPORT!E55 | C22: =MASTER_AR_REPORT!D55 | D22: =MASTER_AR_REPORT!C55 | E22: =MASTER_AR_REPORT!G55 | F22: =MASTER_AR_REPORT!I55 | G22: =MASTER_AR_REPORT!J55 | H22: =MASTER_AR_REPORT!K55 | I22: =MASTER_AR_REPORT!L55 | J22: =MASTER_AR_REPORT!M55 | K22: Pending
A23: 19 | B23: =MASTER_AR_REPORT!E58 | C23: =MASTER_AR_REPORT!D58 | D23: =MASTER_AR_REPORT!C58 | E23: =MASTER_AR_REPORT!G58 | F23: =MASTER_AR_REPORT!I58 | G23: =MASTER_AR_REPORT!J58 | H23: =MASTER_AR_REPORT!K58 | I23: =MASTER_AR_REPORT!L58 | J23: =MASTER_AR_REPORT!M58 | K23: Pending
A24: 20 | B24: =MASTER_AR_REPORT!E60 | C24: =MASTER_AR_REPORT!D60 | D24: =MASTER_AR_REPORT!C60 | E24: =MASTER_AR_REPORT!G60 | F24: =MASTER_AR_REPORT!I60 | G24: =MASTER_AR_REPORT!J60 | H24: =MASTER_AR_REPORT!K60 | I24: =MASTER_AR_REPORT!L60 | J24: =MASTER_AR_REPORT!M60 | K24: Pending
A25: 21 | B25: =MASTER_AR_REPORT!E61 | C25: =MASTER_AR_REPORT!D61 | D25: =MASTER_AR_REPORT!C61 | E25: =MASTER_AR_REPORT!G61 | F25: =MASTER_AR_REPORT!I61 | G25: =MASTER_AR_REPORT!J61 | H25: =MASTER_AR_REPORT!K61 | I25: =MASTER_AR_REPORT!L61 | J25: =MASTER_AR_REPORT!M61 | K25: Pending
A26: 22 | B26: =MASTER_AR_REPORT!E88 | C26: =MASTER_AR_REPORT!D88 | D26: =MASTER_AR_REPORT!C88 | E26: =MASTER_AR_REPORT!G88 | F26: =MASTER_AR_REPORT!I88 | G26: =MASTER_AR_REPORT!J88 | H26: =MASTER_AR_REPORT!K88 | I26: =MASTER_AR_REPORT!L88 | J26: =MASTER_AR_REPORT!M88 | K26: Pending
A27: 23 | B27: =MASTER_AR_REPORT!E89 | C27: =MASTER_AR_REPORT!D89 | D27: =MASTER_AR_REPORT!C89 | E27: =MASTER_AR_REPORT!G89 | F27: =MASTER_AR_REPORT!I89 | G27: =MASTER_AR_REPORT!J89 | H27: =MASTER_AR_REPORT!K89 | I27: =MASTER_AR_REPORT!L89 | J27: =MASTER_AR_REPORT!M89 | K27: Pending
A28: 24 | B28: =MASTER_AR_REPORT!E90 | C28: =MASTER_AR_REPORT!D90 | D28: =MASTER_AR_REPORT!C90 | E28: =MASTER_AR_REPORT!G90 | F28: =MASTER_AR_REPORT!I90 | G28: =MASTER_AR_REPORT!J90 | H28: =MASTER_AR_REPORT!K90 | I28: =MASTER_AR_REPORT!L90 | J28: =MASTER_AR_REPORT!M90 | K28: Pending
A29: 25 | B29: =MASTER_AR_REPORT!E93 | C29: =MASTER_AR_REPORT!D93 | D29: =MASTER_AR_REPORT!C93 | E29: =MASTER_AR_REPORT!G93 | F29: =MASTER_AR_REPORT!I93 | G29: =MASTER_AR_REPORT!J93 | H29: =MASTER_AR_REPORT!K93 | I29: =MASTER_AR_REPORT!L93 | J29: =MASTER_AR_REPORT!M93 | K29: Pending
A30: 26 | B30: =MASTER_AR_REPORT!E94 | C30: =MASTER_AR_REPORT!D94 | D30: =MASTER_AR_REPORT!C94 | E30: =MASTER_AR_REPORT!G94 | F30: =MASTER_AR_REPORT!I94 | G30: =MASTER_AR_REPORT!J94 | H30: =MASTER_AR_REPORT!K94 | I30: =MASTER_AR_REPORT!L94 | J30: =MASTER_AR_REPORT!M94 | K30: Pending
A31: 27 | B31: =MASTER_AR_REPORT!E95 | C31: =MASTER_AR_REPORT!D95 | D31: =MASTER_AR_REPORT!C95 | E31: =MASTER_AR_REPORT!G95 | F31: =MASTER_AR_REPORT!I95 | G31: =MASTER_AR_REPORT!J95 | H31: =MASTER_AR_REPORT!K95 | I31: =MASTER_AR_REPORT!L95 | J31: =MASTER_AR_REPORT!M95 | K31: Pending
A32: 28 | B32: =MASTER_AR_REPORT!E96 | C32: =MASTER_AR_REPORT!D96 | D32: =MASTER_AR_REPORT!C96 | E32: =MASTER_AR_REPORT!G96 | F32: =MASTER_AR_REPORT!I96 | G32: =MASTER_AR_REPORT!J96 | H32: =MASTER_AR_REPORT!K96 | I32: =MASTER_AR_REPORT!L96 | J32: =MASTER_AR_REPORT!M96 | K32: Pending
A33: 29 | B33: =MASTER_AR_REPORT!E97 | C33: =MASTER_AR_REPORT!D97 | D33: =MASTER_AR_REPORT!C97 | E33: =MASTER_AR_REPORT!G97 | F33: =MASTER_AR_REPORT!I97 | G33: =MASTER_AR_REPORT!J97 | H33: =MASTER_AR_REPORT!K97 | I33: =MASTER_AR_REPORT!L97 | J33: =MASTER_AR_REPORT!M97 | K33: Pending
A34: 30 | B34: =MASTER_AR_REPORT!E98 | C34: =MASTER_AR_REPORT!D98 | D34: =MASTER_AR_REPORT!C98 | E34: =MASTER_AR_REPORT!G98 | F34: =MASTER_AR_REPORT!I98 | G34: =MASTER_AR_REPORT!J98 | H34: =MASTER_AR_REPORT!K98 | I34: =MASTER_AR_REPORT!L98 | J34: =MASTER_AR_REPORT!M98 | K34: Pending
A35: 31 | B35: =MASTER_AR_REPORT!E99 | C35: =MASTER_AR_REPORT!D99 | D35: =MASTER_AR_REPORT!C99 | E35: =MASTER_AR_REPORT!G99 | F35: =MASTER_AR_REPORT!I99 | G35: =MASTER_AR_REPORT!J99 | H35: =MASTER_AR_REPORT!K99 | I35: =MASTER_AR_REPORT!L99 | J35: =MASTER_AR_REPORT!M99 | K35: Pending
A36: 32 | B36: =MASTER_AR_REPORT!E103 | C36: =MASTER_AR_REPORT!D103 | D36: =MASTER_AR_REPORT!C103 | E36: =MASTER_AR_REPORT!G103 | F36: =MASTER_AR_REPORT!I103 | G36: =MASTER_AR_REPORT!J103 | H36: =MASTER_AR_REPORT!K103 | I36: =MASTER_AR_REPORT!L103 | J36: =MASTER_AR_REPORT!M103 | K36: Pending
A37: 33 | B37: =MASTER_AR_REPORT!E108 | C37: =MASTER_AR_REPORT!D108 | D37: =MASTER_AR_REPORT!C108 | E37: =MASTER_AR_REPORT!G108 | F37: =MASTER_AR_REPORT!I108 | G37: =MASTER_AR_REPORT!J108 | H37: =MASTER_AR_REPORT!K108 | I37: =MASTER_AR_REPORT!L108 | J37: =MASTER_AR_REPORT!M108 | K37: Pending
A38: 34 | B38: =MASTER_AR_REPORT!E110 | C38: =MASTER_AR_REPORT!D110 | D38: =MASTER_AR_REPORT!C110 | E38: =MASTER_AR_REPORT!G110 | F38: =MASTER_AR_REPORT!I110 | G38: =MASTER_AR_REPORT!J110 | H38: =MASTER_AR_REPORT!K110 | I38: =MASTER_AR_REPORT!L110 | J38: =MASTER_AR_REPORT!M110 | K38: Pending
A39: 35 | B39: =MASTER_AR_REPORT!E111 | C39: =MASTER_AR_REPORT!D111 | D39: =MASTER_AR_REPORT!C111 | E39: =MASTER_AR_REPORT!G111 | F39: =MASTER_AR_REPORT!I111 | G39: =MASTER_AR_REPORT!J111 | H39: =MASTER_AR_REPORT!K111 | I39: =MASTER_AR_REPORT!L111 | J39: =MASTER_AR_REPORT!M111 | K39: Pending
A40: 36 | B40: =MASTER_AR_REPORT!E112 | C40: =MASTER_AR_REPORT!D112 | D40: =MASTER_AR_REPORT!C112 | E40: =MASTER_AR_REPORT!G112 | F40: =MASTER_AR_REPORT!I112 | G40: =MASTER_AR_REPORT!J112 | H40: =MASTER_AR_REPORT!K112 | I40: =MASTER_AR_REPORT!L112 | J40: =MASTER_AR_REPORT!M112 | K40: Pending
A41: 37 | B41: =MASTER_AR_REPORT!E113 | C41: =MASTER_AR_REPORT!D113 | D41: =MASTER_AR_REPORT!C113 | E41: =MASTER_AR_REPORT!G113 | F41: =MASTER_AR_REPORT!I113 | G41: =MASTER_AR_REPORT!J113 | H41: =MASTER_AR_REPORT!K113 | I41: =MASTER_AR_REPORT!L113 | J41: =MASTER_AR_REPORT!M113 | K41: Pending
...

Sheet Watches_Report
A1: AR Aging Report - Watches
A2: Report Date: 21-May-2026
A4: S.No | B4: Source Sheet | C4: Date | D4: Invoice No | E4: Customer Name | F4: Invoice Amount | G4: Due Date | H4: Paid Amount | I4: Outstanding Amount | J4: Days Overdue | K4: Aging Bucket | L4: Risk Level | M4: Follow-up Priority | N4: Call Status | O4: Last Follow-up Notes
A5: 1 | B5: =IF(MASTER_AR_REPORT!B2="","",MASTER_AR_REPORT!B2) | C5: =MASTER_AR_REPORT!C2 | D5: =IF(MASTER_AR_REPORT!D2="","",MASTER_AR_REPORT!D2) | E5: =IF(MASTER_AR_REPORT!E2="","",MASTER_AR_REPORT!E2) | F5: =MASTER_AR_REPORT!F2 | G5: =MASTER_AR_REPORT!G2 | H5: =MASTER_AR_REPORT!H2 | I5: =MASTER_AR_REPORT!I2 | J5: =MASTER_AR_REPORT!J2 | K5: =MASTER_AR_REPORT!K2 | L5: =MASTER_AR_REPORT!L2 | M5: =MASTER_AR_REPORT!M2 | ... O5: =MASTER_AR_REPORT!O2
A6: 2 | B6: =IF(MASTER_AR_REPORT!B3="","",MASTER_AR_REPORT!B3) | C6: =MASTER_AR_REPORT!C3 | D6: =IF(MASTER_AR_REPORT!D3="","",MASTER_AR_REPORT!D3) | E6: =IF(MASTER_AR_REPORT!E3="","",MASTER_AR_REPORT!E3) | F6: =MASTER_AR_REPORT!F3 | G6: =MASTER_AR_REPORT!G3 | H6: =MASTER_AR_REPORT!H3 | I6: =MASTER_AR_REPORT!I3 | J6: =MASTER_AR_REPORT!J3 | K6: =MASTER_AR_REPORT!K3 | L6: =MASTER_AR_REPORT!L3 | M6: =MASTER_AR_REPORT!M3 | ... O6: =MASTER_AR_REPORT!O3
A7: 3 | B7: =IF(MASTER_AR_REPORT!B4="","",MASTER_AR_REPORT!B4) | C7: =MASTER_AR_REPORT!C4 | D7: =IF(MASTER_AR_REPORT!D4="","",MASTER_AR_REPORT!D4) | E7: =IF(MASTER_AR_REPORT!E4="","",MASTER_AR_REPORT!E4) | F7: =MASTER_AR_REPORT!F4 | G7: =MASTER_AR_REPORT!G4 | H7: =MASTER_AR_REPORT!H4 | I7: =MASTER_AR_REPORT!I4 | J7: =MASTER_AR_REPORT!J4 | K7: =MASTER_AR_REPORT!K4 | L7: =MASTER_AR_REPORT!L4 | M7: =MASTER_AR_REPORT!M4 | ... O7: =MASTER_AR_REPORT!O4
A8: 4 | B8: =IF(MASTER_AR_REPORT!B5="","",MASTER_AR_REPORT!B5) | C8: =MASTER_AR_REPORT!C5 | D8: =IF(MASTER_AR_REPORT!D5="","",MASTER_AR_REPORT!D5) | E8: =IF(MASTER_AR_REPORT!E5="","",MASTER_AR_REPORT!E5) | F8: =MASTER_AR_REPORT!F5 | G8: =MASTER_AR_REPORT!G5 | H8: =MASTER_AR_REPORT!H5 | I8: =MASTER_AR_REPORT!I5 | J8: =MASTER_AR_REPORT!J5 | K8: =MASTER_AR_REPORT!K5 | L8: =MASTER_AR_REPORT!L5 | M8: =MASTER_AR_REPORT!M5 | ... O8: =MASTER_AR_REPORT!O5
A9: 5 | B9: =IF(MASTER_AR_REPORT!B6="","",MASTER_AR_REPORT!B6) | C9: =MASTER_AR_REPORT!C6 | D9: =IF(MASTER_AR_REPORT!D6="","",MASTER_AR_REPORT!D6) | E9: =IF(MASTER_AR_REPORT!E6="","",MASTER_AR_REPORT!E6) | F9: =MASTER_AR_REPORT!F6 | G9: =MASTER_AR_REPORT!G6 | H9: =MASTER_AR_REPORT!H6 | I9: =MASTER_AR_REPORT!I6 | J9: =MASTER_AR_REPORT!J6 | K9: =MASTER_AR_REPORT!K6 | L9: =MASTER_AR_REPORT!L6 | M9: =MASTER_AR_REPORT!M6 | ... O9: =MASTER_AR_REPORT!O6
A10: 6 | B10: =IF(MASTER_AR_REPORT!B7="","",MASTER_AR_REPORT!B7) | C10: =MASTER_AR_REPORT!C7 | D10: =IF(MASTER_AR_REPORT!D7="","",MASTER_AR_REPORT!D7) | E10: =IF(MASTER_AR_REPORT!E7="","",MASTER_AR_REPORT!E7) | F10: =MASTER_AR_REPORT!F7 | G10: =MASTER_AR_REPORT!G7 | H10: =MASTER_AR_REPORT!H7 | I10: =MASTER_AR_REPORT!I7 | J10: =MASTER_AR_REPORT!J7 | K10: =MASTER_AR_REPORT!K7 | L10: =MASTER_AR_REPORT!L7 | M10: =MASTER_AR_REPORT!M7 | ... O10: =MASTER_AR_REPORT!O7
A11: 7 | B11: =IF(MASTER_AR_REPORT!B8="","",MASTER_AR_REPORT!B8) | C11: =MASTER_AR_REPORT!C8 | D11: =IF(MASTER_AR_REPORT!D8="","",MASTER_AR_REPORT!D8) | E11: =IF(MASTER_AR_REPORT!E8="","",MASTER_AR_REPORT!E8) | F11: =MASTER_AR_REPORT!F8 | G11: =MASTER_AR_REPORT!G8 | H11: =MASTER_AR_REPORT!H8 | I11: =MASTER_AR_REPORT!I8 | J11: =MASTER_AR_REPORT!J8 | K11: =MASTER_AR_REPORT!K8 | L11: =MASTER_AR_REPORT!L8 | M11: =MASTER_AR_REPORT!M8 | ... O11: =MASTER_AR_REPORT!O8
A12: 8 | B12: =IF(MASTER_AR_REPORT!B9="","",MASTER_AR_REPORT!B9) | C12: =MASTER_AR_REPORT!C9 | D12: =IF(MASTER_AR_REPORT!D9="","",MASTER_AR_REPORT!D9) | E12: =IF(MASTER_AR_REPORT!E9="","",MASTER_AR_REPORT!E9) | F12: =MASTER_AR_REPORT!F9 | G12: =MASTER_AR_REPORT!G9 | H12: =MASTER_AR_REPORT!H9 | I12: =MASTER_AR_REPORT!I9 | J12: =MASTER_AR_REPORT!J9 | K12: =MASTER_AR_REPORT!K9 | L12: =MASTER_AR_REPORT!L9 | M12: =MASTER_AR_REPORT!M9 | ... O12: =MASTER_AR_REPORT!O9
A13: 9 | B13: =IF(MASTER_AR_REPORT!B10="","",MASTER_AR_REPORT!B10) | C13: =MASTER_AR_REPORT!C10 | D13: =IF(MASTER_AR_REPORT!D10="","",MASTER_AR_REPORT!D10) | E13: =IF(MASTER_AR_REPORT!E10="","",MASTER_AR_REPORT!E10) | F13: =MASTER_AR_REPORT!F10 | G13: =MASTER_AR_REPORT!G10 | H13: =MASTER_AR_REPORT!H10 | I13: =MASTER_AR_REPORT!I10 | J13: =MASTER_AR_REPORT!J10 | K13: =MASTER_AR_REPORT!K10 | L13: =MASTER_AR_REPORT!L10 | M13: =MASTER_AR_REPORT!M10 | ... O13: =MASTER_AR_REPORT!O10
A14: 10 | B14: =IF(MASTER_AR_REPORT!B11="","",MASTER_AR_REPORT!B11) | C14: =MASTER_AR_REPORT!C11 | D14: =IF(MASTER_AR_REPORT!D11="","",MASTER_AR_REPORT!D11) | E14: =IF(MASTER_AR_REPORT!E11="","",MASTER_AR_REPORT!E11) | F14: =MASTER_AR_REPORT!F11 | G14: =MASTER_AR_REPORT!G11 | H14: =MASTER_AR_REPORT!H11 | I14: =MASTER_AR_REPORT!I11 | J14: =MASTER_AR_REPORT!J11 | K14: =MASTER_AR_REPORT!K11 | L14: =MASTER_AR_REPORT!L11 | M14: =MASTER_AR_REPORT!M11 | ... O14: =MASTER_AR_REPORT!O11
A15: 11 | B15: =IF(MASTER_AR_REPORT!B12="","",MASTER_AR_REPORT!B12) | C15: =MASTER_AR_REPORT!C12 | D15: =IF(MASTER_AR_REPORT!D12="","",MASTER_AR_REPORT!D12) | E15: =IF(MASTER_AR_REPORT!E12="","",MASTER_AR_REPORT!E12) | F15: =MASTER_AR_REPORT!F12 | G15: =MASTER_AR_REPORT!G12 | H15: =MASTER_AR_REPORT!H12 | I15: =MASTER_AR_REPORT!I12 | J15: =MASTER_AR_REPORT!J12 | K15: =MASTER_AR_REPORT!K12 | L15: =MASTER_AR_REPORT!L12 | M15: =MASTER_AR_REPORT!M12 | ... O15: =MASTER_AR_REPORT!O12
A16: 12 | B16: =IF(MASTER_AR_REPORT!B13="","",MASTER_AR_REPORT!B13) | C16: =MASTER_AR_REPORT!C13 | D16: =IF(MASTER_AR_REPORT!D13="","",MASTER_AR_REPORT!D13) | E16: =IF(MASTER_AR_REPORT!E13="","",MASTER_AR_REPORT!E13) | F16: =MASTER_AR_REPORT!F13 | G16: =MASTER_AR_REPORT!G13 | H16: =MASTER_AR_REPORT!H13 | I16: =MASTER_AR_REPORT!I13 | J16: =MASTER_AR_REPORT!J13 | K16: =MASTER_AR_REPORT!K13 | L16: =MASTER_AR_REPORT!L13 | M16: =MASTER_AR_REPORT!M13 | ... O16: =MASTER_AR_REPORT!O13
... A61: 57 | B61: =IF(MASTER_AR_REPORT!B58="","",MASTER_AR_REPORT!B58) | C61: =MASTER_AR_REPORT!C58 | D61: =IF(MASTER_AR_REPORT!D58="","",MASTER_AR_REPORT!D58) | E61: =IF(MASTER_AR_REPORT!E58="","",MASTER_AR_REPORT!E58) | F61: =MASTER_AR_REPORT!F58 | G61: =MASTER_AR_REPORT!G58 | H61: =MASTER_AR_REPORT!H58 | I61: =MASTER_AR_REPORT!I58 | J61: =MASTER_AR_REPORT!J58 | K61: =MASTER_AR_REPORT!K58 | L61: =MASTER_AR_REPORT!L58 | M61: =MASTER_AR_REPORT!M58 | ... O61: =MASTER_AR_REPORT!O58
E62: TOTAL | F62: =SUM(F5:F61) | H62: =SUM(H5:H61) | I62: =SUM(I5:I61)

Sheet Praveen_Report
A1: AR Aging Report - Praveen
A2: Report Date: 21-May-2026
A4: S.No | B4: Source Sheet | C4: Date | D4: Invoice No | E4: Customer Name | F4: Invoice Amount | G4: Due Date | H4: Paid Amount | I4: Outstanding Amount | J4: Days Overdue | K4: Aging Bucket | L4: Risk Level | M4: Follow-up Priority | N4: Call Status | O4: Last Follow-up Notes
A5: 1 | B5: =IF(MASTER_AR_REPORT!B59="","",MASTER_AR_REPORT!B59) | C5: =MASTER_AR_REPORT!C59 | D5: =IF(MASTER_AR_REPORT!D59="","",MASTER_AR_REPORT!D59) | E5: =IF(MASTER_AR_REPORT!E59="","",MASTER_AR_REPORT!E59) | F5: =MASTER_AR_REPORT!F59 | G5: =MASTER_AR_REPORT!G59 | H5: =MASTER_AR_REPORT!H59 | I5: =MASTER_AR_REPORT!I59 | J5: =MASTER_AR_REPORT!J59 | K5: =MASTER_AR_REPORT!K59 | L5: =MASTER_AR_REPORT!L59 | M5: =MASTER_AR_REPORT!M59 | ... O5: =MASTER_AR_REPORT!O59
A6: 2 | B6: =IF(MASTER_AR_REPORT!B60="","",MASTER_AR_REPORT!B60) | C6: =MASTER_AR_REPORT!C60 | D6: =IF(MASTER_AR_REPORT!D60="","",MASTER_AR_REPORT!D60) | E6: =IF(MASTER_AR_REPORT!E60="","",MASTER_AR_REPORT!E60) | F6: =MASTER_AR_REPORT!F60 | G6: =MASTER_AR_REPORT!G60 | H6: =MASTER_AR_REPORT!H60 | I6: =MASTER_AR_REPORT!I60 | J6: =MASTER_AR_REPORT!J60 | K6: =MASTER_AR_REPORT!K60 | L6: =MASTER_AR_REPORT!L60 | M6: =MASTER_AR_REPORT!M60 | ... O6: =MASTER_AR_REPORT!O60
A7: 3 | B7: =IF(MASTER_AR_REPORT!B61="","",MASTER_AR_REPORT!B61) | C7: =MASTER_AR_REPORT!C61 | D7: =IF(MASTER_AR_REPORT!D61="","",MASTER_AR_REPORT!D61) | E7: =IF(MASTER_AR_REPORT!E61="","",MASTER_AR_REPORT!E61) | F7: =MASTER_AR_REPORT!F61 | G7: =MASTER_AR_REPORT!G61 | H7: =MASTER_AR_REPORT!H61 | I7: =MASTER_AR_REPORT!I61 | J7: =MASTER_AR_REPORT!J61 | K7: =MASTER_AR_REPORT!K61 | L7: =MASTER_AR_REPORT!L61 | M7: =MASTER_AR_REPORT!M61 | ... O7: =MASTER_AR_REPORT!O61
A8: 4 | B8: =IF(MASTER_AR_REPORT!B62="","",MASTER_AR_REPORT!B62) | C8: =MASTER_AR_REPORT!C62 | D8: =IF(MASTER_AR_REPORT!D62="","",MASTER_AR_REPORT!D62) | E8: =IF(MASTER_AR_REPORT!E62="","",MASTER_AR_REPORT!E62) | F8: =MASTER_AR_REPORT!F62 | G8: =MASTER_AR_REPORT!G62 | H8: =MASTER_AR_REPORT!H62 | I8: =MASTER_AR_REPORT!I62 | J8: =MASTER_AR_REPORT!J62 | K8: =MASTER_AR_REPORT!K62 | L8: =MASTER_AR_REPORT!L62 | M8: =MASTER_AR_REPORT!M62 | ... O8: =MASTER_AR_REPORT!O62
A9: 5 | B9: =IF(MASTER_AR_REPORT!B63="","",MASTER_AR_REPORT!B63) | C9: =MASTER_AR_REPORT!C63 | D9: =IF(MASTER_AR_REPORT!D63="","",MASTER_AR_REPORT!D63) | E9: =IF(MASTER_AR_REPORT!E63="","",MASTER_AR_REPORT!E63) | F9: =MASTER_AR_REPORT!F63 | G9: =MASTER_AR_REPORT!G63 | H9: =MASTER_AR_REPORT!H63 | I9: =MASTER_AR_REPORT!I63 | J9: =MASTER_AR_REPORT!J63 | K9: =MASTER_AR_REPORT!K63 | L9: =MASTER_AR_REPORT!L63 | M9: =MASTER_AR_REPORT!M63 | ... O9: =MASTER_AR_REPORT!O63
A10: 6 | B10: =IF(MASTER_AR_REPORT!B64="","",MASTER_AR_REPORT!B64) | C10: =MASTER_AR_REPORT!C64 | D10: =IF(MASTER_AR_REPORT!D64="","",MASTER_AR_REPORT!D64) | E10: =IF(MASTER_AR_REPORT!E64="","",MASTER_AR_REPORT!E64) | F10: =MASTER_AR_REPORT!F64 | G10: =MASTER_AR_REPORT!G64 | H10: =MASTER_AR_REPORT!H64 | I10: =MASTER_AR_REPORT!I64 | J10: =MASTER_AR_REPORT!J64 | K10: =MASTER_AR_REPORT!K64 | L10: =MASTER_AR_REPORT!L64 | M10: =MASTER_AR_REPORT!M64 | ... O10: =MASTER_AR_REPORT!O64
A11: 7 | B11: =IF(MASTER_AR_REPORT!B65="","",MASTER_AR_REPORT!B65) | C11: =MASTER_AR_REPORT!C65 | D11: =IF(MASTER_AR_REPORT!D65="","",MASTER_AR_REPORT!D65) | E11: =IF(MASTER_AR_REPORT!E65="","",MASTER_AR_REPORT!E65) | F11: =MASTER_AR_REPORT!F65 | G11: =MASTER_AR_REPORT!G65 | H11: =MASTER_AR_REPORT!H65 | I11: =MASTER_AR_REPORT!I65 | J11: =MASTER_AR_REPORT!J65 | K11: =MASTER_AR_REPORT!K65 | L11: =MASTER_AR_REPORT!L65 | M11: =MASTER_AR_REPORT!M65 | ... O11: =MASTER_AR_REPORT!O65
A12: 8 | B12: =IF(MASTER_AR_REPORT!B66="","",MASTER_AR_REPORT!B66) | C12: =MASTER_AR_REPORT!C66 | D12: =IF(MASTER_AR_REPORT!D66="","",MASTER_AR_REPORT!D66) | E12: =IF(MASTER_AR_REPORT!E66="","",MASTER_AR_REPORT!E66) | F12: =MASTER_AR_REPORT!F66 | G12: =MASTER_AR_REPORT!G66 | H12: =MASTER_AR_REPORT!H66 | I12: =MASTER_AR_REPORT!I66 | J12: =MASTER_AR_REPORT!J66 | K12: =MASTER_AR_REPORT!K66 | L12: =MASTER_AR_REPORT!L66 | M12: =MASTER_AR_REPORT!M66 | ... O12: =MASTER_AR_REPORT!O66
A13: 9 | B13: =IF(MASTER_AR_REPORT!B67="","",MASTER_AR_REPORT!B67) | C13: =MASTER_AR_REPORT!C67 | D13: =IF(MASTER_AR_REPORT!D67="","",MASTER_AR_REPORT!D67) | E13: =IF(MASTER_AR_REPORT!E67="","",MASTER_AR_REPORT!E67) | F13: =MASTER_AR_REPORT!F67 | G13: =MASTER_AR_REPORT!G67 | H13: =MASTER_AR_REPORT!H67 | I13: =MASTER_AR_REPORT!I67 | J13: =MASTER_AR_REPORT!J67 | K13: =MASTER_AR_REPORT!K67 | L13: =MASTER_AR_REPORT!L67 | M13: =MASTER_AR_REPORT!M67 | ... O13: =MASTER_AR_REPORT!O67
A14: 10 | B14: =IF(MASTER_AR_REPORT!B68="","",MASTER_AR_REPORT!B68) | C14: =MASTER_AR_REPORT!C68 | D14: =IF(MASTER_AR_REPORT!D68="","",MASTER_AR_REPORT!D68) | E14: =IF(MASTER_AR_REPORT!E68="","",MASTER_AR_REPORT!E68) | F14: =MASTER_AR_REPORT!F68 | G14: =MASTER_AR_REPORT!G68 | H14: =MASTER_AR_REPORT!H68 | I14: =MASTER_AR_REPORT!I68 | J14: =MASTER_AR_REPORT!J68 | K14: =MASTER_AR_REPORT!K68 | L14: =MASTER_AR_REPORT!L68 | M14: =MASTER_AR_REPORT!M68 | ... O14: =MASTER_AR_REPORT!O68
A15: 11 | B15: =IF(MASTER_AR_REPORT!B69="","",MASTER_AR_REPORT!B69) | C15: =MASTER_AR_REPORT!C69 | D15: =IF(MASTER_AR_REPORT!D69="","",MASTER_AR_REPORT!D69) | E15: =IF(MASTER_AR_REPORT!E69="","",MASTER_AR_REPORT!E69) | F15: =MASTER_AR_REPORT!F69 | G15: =MASTER_AR_REPORT!G69 | H15: =MASTER_AR_REPORT!H69 | I15: =MASTER_AR_REPORT!I69 | J15: =MASTER_AR_REPORT!J69 | K15: =MASTER_AR_REPORT!K69 | L15: =MASTER_AR_REPORT!L69 | M15: =MASTER_AR_REPORT!M69 | ... O15: =MASTER_AR_REPORT!O69
A16: 12 | B16: =IF(MASTER_AR_REPORT!B70="","",MASTER_AR_REPORT!B70) | C16: =MASTER_AR_REPORT!C70 | D16: =IF(MASTER_AR_REPORT!D70="","",MASTER_AR_REPORT!D70) | E16: =IF(MASTER_AR_REPORT!E70="","",MASTER_AR_REPORT!E70) | F16: =MASTER_AR_REPORT!F70 | G16: =MASTER_AR_REPORT!G70 | H16: =MASTER_AR_REPORT!H70 | I16: =MASTER_AR_REPORT!I70 | J16: =MASTER_AR_REPORT!J70 | K16: =MASTER_AR_REPORT!K70 | L16: =MASTER_AR_REPORT!L70 | M16: =MASTER_AR_REPORT!M70 | ... O16: =MASTER_AR_REPORT!O70
... A79: 75 | B79: =IF(MASTER_AR_REPORT!B133="","",MASTER_AR_REPORT!B133) | C79: =MASTER_AR_REPORT!C133 | D79: =IF(MASTER_AR_REPORT!D133="","",MASTER_AR_REPORT!D133) | E79: =IF(MASTER_AR_REPORT!E133="","",MASTER_AR_REPORT!E133) | F79: =MASTER_AR_REPORT!F133 | G79: =MASTER_AR_REPORT!G133 | H79: =MASTER_AR_REPORT!H133 | I79: =MASTER_AR_REPORT!I133 | J79: =MASTER_AR_REPORT!J133 | K79: =MASTER_AR_REPORT!K133 | L79: =MASTER_AR_REPORT!L133 | M79: =MASTER_AR_REPORT!M133 | ... O79: =MASTER_AR_REPORT!O133
E80: TOTAL | F80: =SUM(F5:F79) | H80: =SUM(H5:H79) | I80: =SUM(I5:I79)

Sheet Mujahid_Report
A1: AR Aging Report - Mujahid
A2: Report Date: 21-May-2026
A4: S.No | B4: Source Sheet | C4: Date | D4: Invoice No | E4: Customer Name | F4: Invoice Amount | G4: Due Date | H4: Paid Amount | I4: Outstanding Amount | J4: Days Overdue | K4: Aging Bucket | L4: Risk Level | M4: Follow-up Priority | N4: Call Status | O4: Last Follow-up Notes
A5: 1 | B5: =IF(MASTER_AR_REPORT!B134="","",MASTER_AR_REPORT!B134) | C5: =MASTER_AR_REPORT!C134 | D5: =IF(MASTER_AR_REPORT!D134="","",MASTER_AR_REPORT!D134) | E5: =IF(MASTER_AR_REPORT!E134="","",MASTER_AR_REPORT!E134) | F5: =MASTER_AR_REPORT!F134 | G5: =MASTER_AR_REPORT!G134 | H5: =MASTER_AR_REPORT!H134 | I5: =MASTER_AR_REPORT!I134 | J5: =MASTER_AR_REPORT!J134 | K5: =MASTER_AR_REPORT!K134 | L5: =MASTER_AR_REPORT!L134 | M5: =MASTER_AR_REPORT!M134 | ... O5: =MASTER_AR_REPORT!O134
A6: 2 | B6: =IF(MASTER_AR_REPORT!B135="","",MASTER_AR_REPORT!B135) | C6: =MASTER_AR_REPORT!C135 | D6: =IF(MASTER_AR_REPORT!D135="","",MASTER_AR_REPORT!D135) | E6: =IF(MASTER_AR_REPORT!E135="","",MASTER_AR_REPORT!E135) | F6: =MASTER_AR_REPORT!F135 | G6: =MASTER_AR_REPORT!G135 | H6: =MASTER_AR_REPORT!H135 | I6: =MASTER_AR_REPORT!I135 | J6: =MASTER_AR_REPORT!J135 | K6: =MASTER_AR_REPORT!K135 | L6: =MASTER_AR_REPORT!L135 | M6: =MASTER_AR_REPORT!M135 | ... O6: =MASTER_AR_REPORT!O135
A7: 3 | B7: =IF(MASTER_AR_REPORT!B136="","",MASTER_AR_REPORT!B136) | C7: =MASTER_AR_REPORT!C136 | D7: =IF(MASTER_AR_REPORT!D136="","",MASTER_AR_REPORT!D136) | E7: =IF(MASTER_AR_REPORT!E136="","",MASTER_AR_REPORT!E136) | F7: =MASTER_AR_REPORT!F136 | G7: =MASTER_AR_REPORT!G136 | H7: =MASTER_AR_REPORT!H136 | I7: =MASTER_AR_REPORT!I136 | J7: =MASTER_AR_REPORT!J136 | K7: =MASTER_AR_REPORT!K136 | L7: =MASTER_AR_REPORT!L136 | M7: =MASTER_AR_REPORT!M136 | ... O7: =MASTER_AR_REPORT!O136
A8: 4 | B8: =IF(MASTER_AR_REPORT!B137="","",MASTER_AR_REPORT!B137) | C8: =MASTER_AR_REPORT!C137 | D8: =IF(MASTER_AR_REPORT!D137="","",MASTER_AR_REPORT!D137) | E8: =IF(MASTER_AR_REPORT!E137="","",MASTER_AR_REPORT!E137) | F8: =MASTER_AR_REPORT!F137 | G8: =MASTER_AR_REPORT!G137 | H8: =MASTER_AR_REPORT!H137 | I8: =MASTER_AR_REPORT!I137 | J8: =MASTER_AR_REPORT!J137 | K8: =MASTER_AR_REPORT!K137 | L8: =MASTER_AR_REPORT!L137 | M8: =MASTER_AR_REPORT!M137 | ... O8: =MASTER_AR_REPORT!O137
A9: 5 | B9: =IF(MASTER_AR_REPORT!B138="","",MASTER_AR_REPORT!B138) | C9: =MASTER_AR_REPORT!C138 | D9: =IF(MASTER_AR_REPORT!D138="","",MASTER_AR_REPORT!D138) | E9: =IF(MASTER_AR_REPORT!E138="","",MASTER_AR_REPORT!E138) | F9: =MASTER_AR_REPORT!F138 | G9: =MASTER_AR_REPORT!G138 | H9: =MASTER_AR_REPORT!H138 | I9: =MASTER_AR_REPORT!I138 | J9: =MASTER_AR_REPORT!J138 | K9: =MASTER_AR_REPORT!K138 | L9: =MASTER_AR_REPORT!L138 | M9: =MASTER_AR_REPORT!M138 | ... O9: =MASTER_AR_REPORT!O138
A10: 6 | B10: =IF(MASTER_AR_REPORT!B139="","",MASTER_AR_REPORT!B139) | C10: =MASTER_AR_REPORT!C139 | D10: =IF(MASTER_AR_REPORT!D139="","",MASTER_AR_REPORT!D139) | E10: =IF(MASTER_AR_REPORT!E139="","",MASTER_AR_REPORT!E139) | F10: =MASTER_AR_REPORT!F139 | G10: =MASTER_AR_REPORT!G139 | H10: =MASTER_AR_REPORT!H139 | I10: =MASTER_AR_REPORT!I139 | J10: =MASTER_AR_REPORT!J139 | K10: =MASTER_AR_REPORT!K139 | L10: =MASTER_AR_REPORT!L139 | M10: =MASTER_AR_REPORT!M139 | ... O10: =MASTER_AR_REPORT!O139
A11: 7 | B11: =IF(MASTER_AR_REPORT!B140="","",MASTER_AR_REPORT!B140) | C11: =MASTER_AR_REPORT!C140 | D11: =IF(MASTER_AR_REPORT!D140="","",MASTER_AR_REPORT!D140) | E11: =IF(MASTER_AR_REPORT!E140="","",MASTER_AR_REPORT!E140) | F11: =MASTER_AR_REPORT!F140 | G11: =MASTER_AR_REPORT!G140 | H11: =MASTER_AR_REPORT!H140 | I11: =MASTER_AR_REPORT!I140 | J11: =MASTER_AR_REPORT!J140 | K11: =MASTER_AR_REPORT!K140 | L11: =MASTER_AR_REPORT!L140 | M11: =MASTER_AR_REPORT!M140 | ... O11: =MASTER_AR_REPORT!O140
A12: 8 | B12: =IF(MASTER_AR_REPORT!B141="","",MASTER_AR_REPORT!B141) | C12: =MASTER_AR_REPORT!C141 | D12: =IF(MASTER_AR_REPORT!D141="","",MASTER_AR_REPORT!D141) | E12: =IF(MASTER_AR_REPORT!E141="","",MASTER_AR_REPORT!E141) | F12: =MASTER_AR_REPORT!F141 | G12: =MASTER_AR_REPORT!G141 | H12: =MASTER_AR_REPORT!H141 | I12: =MASTER_AR_REPORT!I141 | J12: =MASTER_AR_REPORT!J141 | K12: =MASTER_AR_REPORT!K141 | L12: =MASTER_AR_REPORT!L141 | M12: =MASTER_AR_REPORT!M141 | ... O12: =MASTER_AR_REPORT!O141
A13: 9 | B13: =IF(MASTER_AR_REPORT!B142="","",MASTER_AR_REPORT!B142) | C13: =MASTER_AR_REPORT!C142 | D13: =IF(MASTER_AR_REPORT!D142="","",MASTER_AR_REPORT!D142) | E13: =IF(MASTER_AR_REPORT!E142="","",MASTER_AR_REPORT!E142) | F13: =MASTER_AR_REPORT!F142 | G13: =MASTER_AR_REPORT!G142 | H13: =MASTER_AR_REPORT!H142 | I13: =MASTER_AR_REPORT!I142 | J13: =MASTER_AR_REPORT!J142 | K13: =MASTER_AR_REPORT!K142 | L13: =MASTER_AR_REPORT!L142 | M13: =MASTER_AR_REPORT!M142 | ... O13: =MASTER_AR_REPORT!O142
A14: 10 | B14: =IF(MASTER_AR_REPORT!B143="","",MASTER_AR_REPORT!B143) | C14: =MASTER_AR_REPORT!C143 | D14: =IF(MASTER_AR_REPORT!D143="","",MASTER_AR_REPORT!D143) | E14: =IF(MASTER_AR_REPORT!E143="","",MASTER_AR_REPORT!E143) | F14: =MASTER_AR_REPORT!F143 | G14: =MASTER_AR_REPORT!G143 | H14: =MASTER_AR_REPORT!H143 | I14: =MASTER_AR_REPORT!I143 | J14: =MASTER_AR_REPORT!J143 | K14: =MASTER_AR_REPORT!K143 | L14: =MASTER_AR_REPORT!L143 | M14: =MASTER_AR_REPORT!M143 | ... O14: =MASTER_AR_REPORT!O143
A15: 11 | B15: =IF(MASTER_AR_REPORT!B144="","",MASTER_AR_REPORT!B144) | C15: =MASTER_AR_REPORT!C144 | D15: =IF(MASTER_AR_REPORT!D144="","",MASTER_AR_REPORT!D144) | E15: =IF(MASTER_AR_REPORT!E144="","",MASTER_AR_REPORT!E144) | F15: =MASTER_AR_REPORT!F144 | G15: =MASTER_AR_REPORT!G144 | H15: =MASTER_AR_REPORT!H144 | I15: =MASTER_AR_REPORT!I144 | J15: =MASTER_AR_REPORT!J144 | K15: =MASTER_AR_REPORT!K144 | L15: =MASTER_AR_REPORT!L144 | M15: =MASTER_AR_REPORT!M144 | ... O15: =MASTER_AR_REPORT!O144
A16: 12 | B16: =IF(MASTER_AR_REPORT!B145="","",MASTER_AR_REPORT!B145) | C16: =MASTER_AR_REPORT!C145 | D16: =IF(MASTER_AR_REPORT!D145="","",MASTER_AR_REPORT!D145) | E16: =IF(MASTER_AR_REPORT!E145="","",MASTER_AR_REPORT!E145) | F16: =MASTER_AR_REPORT!F145 | G16: =MASTER_AR_REPORT!G145 | H16: =MASTER_AR_REPORT!H145 | I16: =MASTER_AR_REPORT!I145 | J16: =MASTER_AR_REPORT!J145 | K16: =MASTER_AR_REPORT!K145 | L16: =MASTER_AR_REPORT!L145 | M16: =MASTER_AR_REPORT!M145 | ... O16: =MASTER_AR_REPORT!O145
... A75: 71 | B75: =IF(MASTER_AR_REPORT!B204="","",MASTER_AR_REPORT!B204) | C75: =MASTER_AR_REPORT!C204 | D75: =IF(MASTER_AR_REPORT!D204="","",MASTER_AR_REPORT!D204) | E75: =IF(MASTER_AR_REPORT!E204="","",MASTER_AR_REPORT!E204) | F75: =MASTER_AR_REPORT!F204 | G75: =MASTER_AR_REPORT!G204 | H75: =MASTER_AR_REPORT!H204 | I75: =MASTER_AR_REPORT!I204 | J75: =MASTER_AR_REPORT!J204 | K75: =MASTER_AR_REPORT!K204 | L75: =MASTER_AR_REPORT!L204 | M75: =MASTER_AR_REPORT!M204 | ... O75: =MASTER_AR_REPORT!O204
E76: TOTAL | F76: =SUM(F5:F75) | H76: =SUM(H5:H75) | I76: =SUM(I5:I75)

Sheet Vinod_Report
A1: AR Aging Report - Vinod
A2: Report Date: 21-May-2026
A4: S.No | B4: Source Sheet | C4: Date | D4: Invoice No | E4: Customer Name | F4: Invoice Amount | G4: Due Date | H4: Paid Amount | I4: Outstanding Amount | J4: Days Overdue | K4: Aging Bucket | L4: Risk Level | M4: Follow-up Priority | N4: Call Status | O4: Last Follow-up Notes
A5: 1 | B5: =IF(MASTER_AR_REPORT!B205="","",MASTER_AR_REPORT!B205) | C5: =MASTER_AR_REPORT!C205 | D5: =IF(MASTER_AR_REPORT!D205="","",MASTER_AR_REPORT!D205) | E5: =IF(MASTER_AR_REPORT!E205="","",MASTER_AR_REPORT!E205) | F5: =MASTER_AR_REPORT!F205 | G5: =MASTER_AR_REPORT!G205 | H5: =MASTER_AR_REPORT!H205 | I5: =MASTER_AR_REPORT!I205 | J5: =MASTER_AR_REPORT!J205 | K5: =MASTER_AR_REPORT!K205 | L5: =MASTER_AR_REPORT!L205 | M5: =MASTER_AR_REPORT!M205 | ... O5: =MASTER_AR_REPORT!O205
A6: 2 | B6: =IF(MASTER_AR_REPORT!B206="","",MASTER_AR_REPORT!B206) | C6: =MASTER_AR_REPORT!C206 | D6: =IF(MASTER_AR_REPORT!D206="","",MASTER_AR_REPORT!D206) | E6: =IF(MASTER_AR_REPORT!E206="","",MASTER_AR_REPORT!E206) | F6: =MASTER_AR_REPORT!F206 | G6: =MASTER_AR_REPORT!G206 | H6: =MASTER_AR_REPORT!H206 | I6: =MASTER_AR_REPORT!I206 | J6: =MASTER_AR_REPORT!J206 | K6: =MASTER_AR_REPORT!K206 | L6: =MASTER_AR_REPORT!L206 | M6: =MASTER_AR_REPORT!M206 | ... O6: =MASTER_AR_REPORT!O206
A7: 3 | B7: =IF(MASTER_AR_REPORT!B207="","",MASTER_AR_REPORT!B207) | C7: =MASTER_AR_REPORT!C207 | D7: =IF(MASTER_AR_REPORT!D207="","",MASTER_AR_REPORT!D207) | E7: =IF(MASTER_AR_REPORT!E207="","",MASTER_AR_REPORT!E207) | F7: =MASTER_AR_REPORT!F207 | G7: =MASTER_AR_REPORT!G207 | H7: =MASTER_AR_REPORT!H207 | I7: =MASTER_AR_REPORT!I207 | J7: =MASTER_AR_REPORT!J207 | K7: =MASTER_AR_REPORT!K207 | L7: =MASTER_AR_REPORT!L207 | M7: =MASTER_AR_REPORT!M207 | ... O7: =MASTER_AR_REPORT!O207
A8: 4 | B8: =IF(MASTER_AR_REPORT!B208="","",MASTER_AR_REPORT!B208) | C8: =MASTER_AR_REPORT!C208 | D8: =IF(MASTER_AR_REPORT!D208="","",MASTER_AR_REPORT!D208) | E8: =IF(MASTER_AR_REPORT!E208="","",MASTER_AR_REPORT!E208) | F8: =MASTER_AR_REPORT!F208 | G8: =MASTER_AR_REPORT!G208 | H8: =MASTER_AR_REPORT!H208 | I8: =MASTER_AR_REPORT!I208 | J8: =MASTER_AR_REPORT!J208 | K8: =MASTER_AR_REPORT!K208 | L8: =MASTER_AR_REPORT!L208 | M8: =MASTER_AR_REPORT!M208 | ... O8: =MASTER_AR_REPORT!O208
A9: 5 | B9: =IF(MASTER_AR_REPORT!B209="","",MASTER_AR_REPORT!B209) | C9: =MASTER_AR_REPORT!C209 | D9: =IF(MASTER_AR_REPORT!D209="","",MASTER_AR_REPORT!D209) | E9: =IF(MASTER_AR_REPORT!E209="","",MASTER_AR_REPORT!E209) | F9: =MASTER_AR_REPORT!F209 | G9: =MASTER_AR_REPORT!G209 | H9: =MASTER_AR_REPORT!H209 | I9: =MASTER_AR_REPORT!I209 | J9: =MASTER_AR_REPORT!J209 | K9: =MASTER_AR_REPORT!K209 | L9: =MASTER_AR_REPORT!L209 | M9: =MASTER_AR_REPORT!M209 | ... O9: =MASTER_AR_REPORT!O209
A10: 6 | B10: =IF(MASTER_AR_REPORT!B210="","",MASTER_AR_REPORT!B210) | C10: =MASTER_AR_REPORT!C210 | D10: =IF(MASTER_AR_REPORT!D210="","",MASTER_AR_REPORT!D210) | E10: =IF(MASTER_AR_REPORT!E210="","",MASTER_AR_REPORT!E210) | F10: =MASTER_AR_REPORT!F210 | G10: =MASTER_AR_REPORT!G210 | H10: =MASTER_AR_REPORT!H210 | I10: =MASTER_AR_REPORT!I210 | J10: =MASTER_AR_REPORT!J210 | K10: =MASTER_AR_REPORT!K210 | L10: =MASTER_AR_REPORT!L210 | M10: =MASTER_AR_REPORT!M210 | ... O10: =MASTER_AR_REPORT!O210
