Workbook

Sheet DASHBOARD
A1: SkyLimit AR AGING DASHBOARD
A2: As of 21-May-2026 | Automated AR Aging Report
A4: Total Outstanding | D4: Total Collected (Paid) | G4: Total Pending
A5: =SUMIFS(MASTER_AR_REPORT!I:I,MASTER_AR_REPORT!I:I,">0") -> 11520215 | D5: =SUM(MASTER_AR_REPORT!H:H) -> 403187 | G5: =SUMIFS(MASTER_AR_REPORT!I:I,MASTER_AR_REPORT!I:I,">0") -> 11520215
A7: High Risk (90+) | D7: Total Customers | G7: Total Invoices
A8: =SUMIFS(MASTER_AR_REPORT!I:I,MASTER_AR_REPORT!L:L,"HIGH RISK") -> 1938410 | D8: {=SUMPRODUCT((MASTER_AR_REPORT!E2:E99999<>"")/COUNTIF(MASTER_AR_REPORT!E2:E99999,MASTER_AR_REPORT!E2:E99999&""))} -> 134 | G8: =COUNTA(MASTER_AR_REPORT!A2:A99999) -> 265
A11: AGING BUCKET SUMMARY
A12: Aging Bucket | B12: Invoice Count | C12: Total Amount | D12: % of Total
A13: Current | B13: =COUNTIFS(MASTER_AR_REPORT!K:K,"Current") -> 11 | C13: =SUMIFS(MASTER_AR_REPORT!I:I,MASTER_AR_REPORT!K:K,"Current") -> 0 | D13: =IF(C17=0,0,C13/C17) -> 0
A14: 0-30 Days | B14: =COUNTIFS(MASTER_AR_REPORT!K:K,"0-30 Days") -> 114 | C14: =SUMIFS(MASTER_AR_REPORT!I:I,MASTER_AR_REPORT!K:K,"0-30 Days") -> 7393638 | D14: =IF(C17=0,0,C14/C17) -> 3.8142797
A15: 31-60 Days | B15: =COUNTIFS(MASTER_AR_REPORT!K:K,"31-60 Days") -> 57 | C15: =SUMIFS(MASTER_AR_REPORT!I:I,MASTER_AR_REPORT!K:K,"31-60 Days") -> 1057014 | D15: =IF(C17=0,0,C15/C17) -> 0.5452995
A16: 61-90 Days | B16: =COUNTIFS(MASTER_AR_REPORT!K:K,"61-90 Days") -> 24 | C16: =SUMIFS(MASTER_AR_REPORT!I:I,MASTER_AR_REPORT!K:K,"61-90 Days") -> 1131153 | D16: =IF(C17=0,0,C16/C17) -> 0.58354682
A17: 90+ Days | B17: =COUNTIFS(MASTER_AR_REPORT!K:K,"90+ Days") -> 59 | C17: =SUMIFS(MASTER_AR_REPORT!I:I,MASTER_AR_REPORT!K:K,"90+ Days") -> 1938410 | D17: =IF(C17=0,0,C17/C17) -> 1
A18: TOTAL | B18: =SUM(B13:B17) -> 265 | C18: =SUM(C13:C17) -> 11520215 | D18: =SUM(D13:D17) -> 5.943126
A20: COLLECTOR-WISE SUMMARY
A21: Collector | B21: Invoice Count | C21: Total Outstanding | D21: High Risk Amt
A22: Watches | B22: =COUNTIFS(MASTER_AR_REPORT!B:B,"Watches",MASTER_AR_REPORT!I:I,">0") -> 55 | C22: =Watches_Report!I62 -> 5709071 | D22: =SUMIFS(MASTER_AR_REPORT!I:I,MASTER_AR_REPORT!B:B,"Watches",MASTER_AR_REPORT!L:L,"HIGH RISK") -> 96601.03
A23: Praveen | B23: =COUNTIFS(MASTER_AR_REPORT!B:B,"Praveen",MASTER_AR_REPORT!I:I,">0") -> 75 | C23: =Praveen_Report!I80 -> 644027 | D23: =SUMIFS(MASTER_AR_REPORT!I:I,MASTER_AR_REPORT!B:B,"Praveen",MASTER_AR_REPORT!L:L,"HIGH RISK") -> 192283
A24: Mujahid | B24: =COUNTIFS(MASTER_AR_REPORT!B:B,"Mujahid",MASTER_AR_REPORT!I:I,">0") -> 69 | C24: =Mujahid_Report!I76 -> 4527691 | D24: =SUMIFS(MASTER_AR_REPORT!I:I,MASTER_AR_REPORT!B:B,"Mujahid",MASTER_AR_REPORT!L:L,"HIGH RISK") -> 1604966
A25: Vinod | B25: =COUNTIFS(MASTER_AR_REPORT!B:B,"Vinod",MASTER_AR_REPORT!I:I,">0") -> 55 | C25: =Vinod_Report!I67 -> 639426 | D25: =SUMIFS(MASTER_AR_REPORT!I:I,MASTER_AR_REPORT!B:B,"Vinod",MASTER_AR_REPORT!L:L,"HIGH RISK") -> 44560
A26: TOTAL | B26: =SUM(B22:B25) -> 254 | C26: =SUM(C22:C25) -> 11520215 | D26: =SUM(D22:D25) -> 1938410
A28: TOP CUSTOMERS BY OUTSTANDING
A29: Customer Name | B29: Invoice Count | C29: Total Outstanding | D29: Risk Level
A30: RAMESH WATCH CO PVT LTD K-INORBIT | B30: 33 | C30: 5136364 | D30: HIGH RISK
A31: Ram Stationery Mart | B31: 15 | C31: 1387750.9 | D31: HIGH RISK
A32: Dynamic Computer & Stationery | B32: 8 | C32: 760353 | D32: HIGH RISK
A33: Shanker Stationery Mart | B33: 1 | C33: 743012 | D33: Low
A34: RENUKA STATIONERS | B34: 3 | C34: 289589 | D34: Low
A35: KISHORE WATCH CO | B35: 4 | C35: 228285 | D35: HIGH RISK
A36: K D M MARKETING | B36: 2 | C36: 202181 | D36: HIGH RISK
A37: Siddi Times & Electronics | B37: 1 | C37: 149682 | D37: Low
A38: Nandi Arts Stationery | B38: 2 | C38: 146106 | D38: Low
A39: V Raja Stationery | B39: 2 | C39: 141197 | D39: Low-Medium
A40: Vardhman Computer & Stationery | B40: 2 | C40: 137021 | D40: Low
A41: N. PRIYA STATIONARY | B41: 1 | C41: 135197 | D41: Low
... A44: Maruti watche & electronics | B44: 6 | C44: 111503 | D44: Low

Sheet MASTER_AR_REPORT
A1: S.No | B1: Source Sheet | C1: Date | D1: Invoice No | E1: Customer Name | F1: Invoice Amount | G1: Due Date | H1: Paid Amount | I1: Outstanding Amount | J1: Days Overdue | K1: Aging Bucket | L1: Risk Level | M1: Follow-up Priority | N1: Call Status | O1: Last Follow-up Notes
A2: 1 | B2: Watches | C2: 46144 | D2: SLGCW/46/26-27 | E2: C. Ramchander Watch Co. | F2: 1400 | G2: 46144 | H2: 0 | I2: =MAX(0,F2-H2) -> 1400 | J2: =IF(G2="",0,MAX(0,TODAY()-G2)) -> 20 | K2: =IF(I2<=0,"Current",IF(J2<=30,"0-30 Days",IF(J2<=60,"31-60 Days",IF(J2<=90,"61-90 Days","90+ Days")))) -> 0-30 Days | L2: =IF(I2<=0,"-",IF(J2<=30,"Low",IF(J2<=60,"Low-Medium",IF(J2<=90,"Medium","HIGH RISK")))) -> Low | M2: =IF(I2<=0,"-",IF(J2<=30,"Normal",IF(J2<=60,"Medium",IF(J2<=90,"Urgent","Immediate Action")))) -> Normal | N2: Pending | O2: We need to give Credit Note
A3: 2 | B3: Watches | C3: 45716 | D3: SLGCW/1077/24-25 | E3: KHALEEL WATCH CO. | F3: 159.67 | G3: 45716 | H3: 0 | I3: =MAX(0,F3-H3) -> 159.67 | J3: =IF(G3="",0,MAX(0,TODAY()-G3)) -> 448 | K3: =IF(I3<=0,"Current",IF(J3<=30,"0-30 Days",IF(J3<=60,"31-60 Days",IF(J3<=90,"61-90 Days","90+ Days")))) -> 90+ Days | L3: =IF(I3<=0,"-",IF(J3<=30,"Low",IF(J3<=60,"Low-Medium",IF(J3<=90,"Medium","HIGH RISK")))) -> HIGH RISK | M3: =IF(I3<=0,"-",IF(J3<=30,"Normal",IF(J3<=60,"Medium",IF(J3<=90,"Urgent","Immediate Action")))) -> Immediate Action | N3: Pending | O3: Sponge Not recived - Send DSO
A4: 3 | B4: Watches | C4: 46013 | D4: SLGCW/1035/25-26 | E4: KHALEEL WATCH CO. | F4: 383 | G4: 46043 | H4: 0 | I4: =MAX(0,F4-H4) -> 383 | J4: =IF(G4="",0,MAX(0,TODAY()-G4)) -> 121 | K4: =IF(I4<=0,"Current",IF(J4<=30,"0-30 Days",IF(J4<=60,"31-60 Days",IF(J4<=90,"61-90 Days","90+ Days")))) -> 90+ Days | L4: =IF(I4<=0,"-",IF(J4<=30,"Low",IF(J4<=60,"Low-Medium",IF(J4<=90,"Medium","HIGH RISK")))) -> HIGH RISK | M4: =IF(I4<=0,"-",IF(J4<=30,"Normal",IF(J4<=60,"Medium",IF(J4<=90,"Urgent","Immediate Action")))) -> Immediate Action | N4: Pending | O4: He will Pay - Follow Up Needed
A5: 4 | B5: Watches | C5: 45996 | D5: SLGCW/969/25-26 | E5: KISHORE WATCH CO | F5: 2852 | G5: 46041 | H5: 0 | I5: =MAX(0,F5-H5) -> 2852 | J5: =IF(G5="",0,MAX(0,TODAY()-G5)) -> 123 | K5: =IF(I5<=0,"Current",IF(J5<=30,"0-30 Days",IF(J5<=60,"31-60 Days",IF(J5<=90,"61-90 Days","90+ Days")))) -> 90+ Days | L5: =IF(I5<=0,"-",IF(J5<=30,"Low",IF(J5<=60,"Low-Medium",IF(J5<=90,"Medium","HIGH RISK")))) -> HIGH RISK | M5: =IF(I5<=0,"-",IF(J5<=30,"Normal",IF(J5<=60,"Medium",IF(J5<=90,"Urgent","Immediate Action")))) -> Immediate Action | N5: Pending | O5: Bill not available
A6: 5 | B6: Watches | C6: 46139 | D6: SLGCW/25/26-27 | E6: KISHORE WATCH CO | F6: 196667 | G6: 46184 | H6: 0 | I6: =MAX(0,F6-H6) -> 196667 | J6: =IF(G6="",0,MAX(0,TODAY()-G6)) -> 0 | K6: =IF(I6<=0,"Current",IF(J6<=30,"0-30 Days",IF(J6<=60,"31-60 Days",IF(J6<=90,"61-90 Days","90+ Days")))) -> 0-30 Days | L6: =IF(I6<=0,"-",IF(J6<=30,"Low",IF(J6<=60,"Low-Medium",IF(J6<=90,"Medium","HIGH RISK")))) -> Low | M6: =IF(I6<=0,"-",IF(J6<=30,"Normal",IF(J6<=60,"Medium",IF(J6<=90,"Urgent","Immediate Action")))) -> Normal | N6: Pending
A7: 6 | B7: Watches | C7: 46144 | D7: SLGCW/51/26-27 | E7: KISHORE WATCH CO | F7: 9035 | G7: 46189 | H7: 0 | I7: =MAX(0,F7-H7) -> 9035 | J7: =IF(G7="",0,MAX(0,TODAY()-G7)) -> 0 | K7: =IF(I7<=0,"Current",IF(J7<=30,"0-30 Days",IF(J7<=60,"31-60 Days",IF(J7<=90,"61-90 Days","90+ Days")))) -> 0-30 Days | L7: =IF(I7<=0,"-",IF(J7<=30,"Low",IF(J7<=60,"Low-Medium",IF(J7<=90,"Medium","HIGH RISK")))) -> Low | M7: =IF(I7<=0,"-",IF(J7<=30,"Normal",IF(J7<=60,"Medium",IF(J7<=90,"Urgent","Immediate Action")))) -> Normal | N7: Pending
A8: 7 | B8: Watches | C8: 46148 | D8: SLGCW/59/26-27 | E8: KISHORE WATCH CO | F8: 19731 | G8: 46193 | H8: 0 | I8: =MAX(0,F8-H8) -> 19731 | J8: =IF(G8="",0,MAX(0,TODAY()-G8)) -> 0 | K8: =IF(I8<=0,"Current",IF(J8<=30,"0-30 Days",IF(J8<=60,"31-60 Days",IF(J8<=90,"61-90 Days","90+ Days")))) -> 0-30 Days | L8: =IF(I8<=0,"-",IF(J8<=30,"Low",IF(J8<=60,"Low-Medium",IF(J8<=90,"Medium","HIGH RISK")))) -> Low | M8: =IF(I8<=0,"-",IF(J8<=30,"Normal",IF(J8<=60,"Medium",IF(J8<=90,"Urgent","Immediate Action")))) -> Normal | N8: Pending
A9: 8 | B9: Watches | C9: 46136 | D9: SLGCW/15/26-27 | E9: Maruti watche & electronics | F9: 13163 | G9: 46181 | H9: 0 | I9: =MAX(0,F9-H9) -> 13163 | J9: =IF(G9="",0,MAX(0,TODAY()-G9)) -> 0 | K9: =IF(I9<=0,"Current",IF(J9<=30,"0-30 Days",IF(J9<=60,"31-60 Days",IF(J9<=90,"61-90 Days","90+ Days")))) -> 0-30 Days | L9: =IF(I9<=0,"-",IF(J9<=30,"Low",IF(J9<=60,"Low-Medium",IF(J9<=90,"Medium","HIGH RISK")))) -> Low | M9: =IF(I9<=0,"-",IF(J9<=30,"Normal",IF(J9<=60,"Medium",IF(J9<=90,"Urgent","Immediate Action")))) -> Normal | N9: Pending
A10: 9 | B10: Watches | C10: 46142 | D10: SLGCW/40/26-27 | E10: Maruti watche & electronics | F10: 48979 | G10: 46187 | H10: 0 | I10: =MAX(0,F10-H10) -> 48979 | J10: =IF(G10="",0,MAX(0,TODAY()-G10)) -> 0 | K10: =IF(I10<=0,"Current",IF(J10<=30,"0-30 Days",IF(J10<=60,"31-60 Days",IF(J10<=90,"61-90 Days","90+ Days")))) -> 0-30 Days | L10: =IF(I10<=0,"-",IF(J10<=30,"Low",IF(J10<=60,"Low-Medium",IF(J10<=90,"Medium","HIGH RISK")))) -> Low | M10: =IF(I10<=0,"-",IF(J10<=30,"Normal",IF(J10<=60,"Medium",IF(J10<=90,"Urgent","Immediate Action")))) -> Normal | N10: Pending
A11: 10 | B11: Watches | C11: 46144 | D11: SLGCW/53/26-27 | E11: Maruti watche & electronics | F11: 22969 | G11: 46189 | H11: 0 | I11: =MAX(0,F11-H11) -> 22969 | J11: =IF(G11="",0,MAX(0,TODAY()-G11)) -> 0 | K11: =IF(I11<=0,"Current",IF(J11<=30,"0-30 Days",IF(J11<=60,"31-60 Days",IF(J11<=90,"61-90 Days","90+ Days")))) -> 0-30 Days | L11: =IF(I11<=0,"-",IF(J11<=30,"Low",IF(J11<=60,"Low-Medium",IF(J11<=90,"Medium","HIGH RISK")))) -> Low | M11: =IF(I11<=0,"-",IF(J11<=30,"Normal",IF(J11<=60,"Medium",IF(J11<=90,"Urgent","Immediate Action")))) -> Normal | N11: Pending
A12: 11 | B12: Watches | C12: 46149 | D12: SLGCW/61/26-27 | E12: Maruti watche & electronics | F12: 14355 | G12: 46150 | H12: 0 | I12: =MAX(0,F12-H12) -> 14355 | J12: =IF(G12="",0,MAX(0,TODAY()-G12)) -> 14 | K12: =IF(I12<=0,"Current",IF(J12<=30,"0-30 Days",IF(J12<=60,"31-60 Days",IF(J12<=90,"61-90 Days","90+ Days")))) -> 0-30 Days | L12: =IF(I12<=0,"-",IF(J12<=30,"Low",IF(J12<=60,"Low-Medium",IF(J12<=90,"Medium","HIGH RISK")))) -> Low | M12: =IF(I12<=0,"-",IF(J12<=30,"Normal",IF(J12<=60,"Medium",IF(J12<=90,"Urgent","Immediate Action")))) -> Normal | N12: Pending | O12: Number Busy
A13: 12 | B13: Watches | C13: 46157 | D13: SLGCW/65/26-27 | E13: Maruti watche & electronics | F13: 3281 | G13: 46158 | H13: 0 | I13: =MAX(0,F13-H13) -> 3281 | J13: =IF(G13="",0,MAX(0,TODAY()-G13)) -> 6 | K13: =IF(I13<=0,"Current",IF(J13<=30,"0-30 Days",IF(J13<=60,"31-60 Days",IF(J13<=90,"61-90 Days","90+ Days")))) -> 0-30 Days | L13: =IF(I13<=0,"-",IF(J13<=30,"Low",IF(J13<=60,"Low-Medium",IF(J13<=90,"Medium","HIGH RISK")))) -> Low | M13: =IF(I13<=0,"-",IF(J13<=30,"Normal",IF(J13<=60,"Medium",IF(J13<=90,"Urgent","Immediate Action")))) -> Normal | N13: Pending | O13: Number Busy
A14: 13 | B14: Watches | C14: 46158 | D14: SLGCW/67/26-27 | E14: Maruti watche & electronics | F14: 8756 | G14: 46159 | H14: 0 | I14: =MAX(0,F14-H14) -> 8756 | J14: =IF(G14="",0,MAX(0,TODAY()-G14)) -> 5 | K14: =IF(I14<=0,"Current",IF(J14<=30,"0-30 Days",IF(J14<=60,"31-60 Days",IF(J14<=90,"61-90 Days","90+ Days")))) -> 0-30 Days | L14: =IF(I14<=0,"-",IF(J14<=30,"Low",IF(J14<=60,"Low-Medium",IF(J14<=90,"Medium","HIGH RISK")))) -> Low | M14: =IF(I14<=0,"-",IF(J14<=30,"Normal",IF(J14<=60,"Medium",IF(J14<=90,"Urgent","Immediate Action")))) -> Normal | N14: Pending | O14: Number Busy
A15: 14 | B15: Watches | C15: 45705 | D15: SLGCW/1043/24-25 | E15: MILAP GENERAL STORES | F15: 560 | G15: 45705 | H15: 0 | I15: =MAX(0,F15-H15) -> 560 | J15: =IF(G15="",0,MAX(0,TODAY()-G15)) -> 459 | K15: =IF(I15<=0,"Current",IF(J15<=30,"0-30 Days",IF(J15<=60,"31-60 Days",IF(J15<=90,"61-90 Days","90+ Days")))) -> 90+ Days | L15: =IF(I15<=0,"-",IF(J15<=30,"Low",IF(J15<=60,"Low-Medium",IF(J15<=90,"Medium","HIGH RISK")))) -> HIGH RISK | M15: =IF(I15<=0,"-",IF(J15<=30,"Normal",IF(J15<=60,"Medium",IF(J15<=90,"Urgent","Immediate Action")))) -> Immediate Action | N15: Pending | O15: Not Lifting Call
A16: 15 | B16: Watches | C16: 45708 | D16: SLGCW/1061/24-25 | E16: MILAP GENERAL STORES | F16: 103.36 | G16: 45708 | H16: 0 | I16: =MAX(0,F16-H16) -> 103.36 | J16: =IF(G16="",0,MAX(0,TODAY()-G16)) -> 456 | K16: =IF(I16<=0,"Current",IF(J16<=30,"0-30 Days",IF(J16<=60,"31-60 Days",IF(J16<=90,"61-90 Days","90+ Days")))) -> 90+ Days | L16: =IF(I16<=0,"-",IF(J16<=30,"Low",IF(J16<=60,"Low-Medium",IF(J16<=90,"Medium","HIGH RISK")))) -> HIGH RISK | M16: =IF(I16<=0,"-",IF(J16<=30,"Normal",IF(J16<=60,"Medium",IF(J16<=90,"Urgent","Immediate Action")))) -> Immediate Action | N16: Pending | O16: Not Lifting Call
A17: 16 | B17: Watches | C17: 46144 | D17: SLGCW/58/26-27 | E17: NAZEER & SONS | F17: 14781 | G17: 46174 | H17: 0 | I17: =MAX(0,F17-H17) -> 14781 | J17: =IF(G17="",0,MAX(0,TODAY()-G17)) -> 0 | K17: =IF(I17<=0,"Current",IF(J17<=30,"0-30 Days",IF(J17<=60,"31-60 Days",IF(J17<=90,"61-90 Days","90+ Days")))) -> 0-30 Days | L17: =IF(I17<=0,"-",IF(J17<=30,"Low",IF(J17<=60,"Low-Medium",IF(J17<=90,"Medium","HIGH RISK")))) -> Low | M17: =IF(I17<=0,"-",IF(J17<=30,"Normal",IF(J17<=60,"Medium",IF(J17<=90,"Urgent","Immediate Action")))) -> Normal | N17: Pending
A18: 17 | B18: Watches | C18: 46150 | D18: SLGCW/62/26-27 | E18: NAZEER & SONS | F18: 12783 | G18: 46151 | H18: 12783 | I18: =MAX(0,F18-H18) -> 0 | J18: =IF(G18="",0,MAX(0,TODAY()-G18)) -> 13 | K18: =IF(I18<=0,"Current",IF(J18<=30,"0-30 Days",IF(J18<=60,"31-60 Days",IF(J18<=90,"61-90 Days","90+ Days")))) -> Current | L18: =IF(I18<=0,"-",IF(J18<=30,"Low",IF(J18<=60,"Low-Medium",IF(J18<=90,"Medium","HIGH RISK")))) -> - | M18: =IF(I18<=0,"-",IF(J18<=30,"Normal",IF(J18<=60,"Medium",IF(J18<=90,"Urgent","Immediate Action")))) -> - | N18: Pending | O18: Customer says Cheque already Paid
A19: 18 | B19: Watches | C19: 45667 | D19: SLGCW/898/24-25 | E19: RAMESH WATCH CO PVT LTD K-INORBIT | F19: 92000 | G19: 45667 | H19: 0 | I19: =MAX(0,F19-H19) -> 92000 | J19: =IF(G19="",0,MAX(0,TODAY()-G19)) -> 497 | K19: =IF(I19<=0,"Current",IF(J19<=30,"0-30 Days",IF(J19<=60,"31-60 Days",IF(J19<=90,"61-90 Days","90+ Days")))) -> 90+ Days | L19: =IF(I19<=0,"-",IF(J19<=30,"Low",IF(J19<=60,"Low-Medium",IF(J19<=90,"Medium","HIGH RISK")))) -> HIGH RISK | M19: =IF(I19<=0,"-",IF(J19<=30,"Normal",IF(J19<=60,"Medium",IF(J19<=90,"Urgent","Immediate Action")))) -> Immediate Action | N19: Pending | O19: Issue
A20: 19 | B20: Watches | C20: 46044 | D20: SLGCW/1138/25-26 | E20: RAMESH WATCH CO PVT LTD K-INORBIT | F20: 74393 | G20: 46089 | H20: 0 | I20: =MAX(0,F20-H20) -> 74393 | J20: =IF(G20="",0,MAX(0,TODAY()-G20)) -> 75 | K20: =IF(I20<=0,"Current",IF(J20<=30,"0-30 Days",IF(J20<=60,"31-60 Days",IF(J20<=90,"61-90 Days","90+ Days")))) -> 61-90 Days | L20: =IF(I20<=0,"-",IF(J20<=30,"Low",IF(J20<=60,"Low-Medium",IF(J20<=90,"Medium","HIGH RISK")))) -> Medium | M20: =IF(I20<=0,"-",IF(J20<=30,"Normal",IF(J20<=60,"Medium",IF(J20<=90,"Urgent","Immediate Action")))) -> Urgent | N20: Pending | O20: DSO will collect
A21: 20 | B21: Watches | C21: 46045 | D21: SLGCW/1150/25-26 | E21: RAMESH WATCH CO PVT LTD K-INORBIT | F21: 263334 | G21: 46090 | H21: 0 | I21: =MAX(0,F21-H21) -> 263334 | J21: =IF(G21="",0,MAX(0,TODAY()-G21)) -> 74 | K21: =IF(I21<=0,"Current",IF(J21<=30,"0-30 Days",IF(J21<=60,"31-60 Days",IF(J21<=90,"61-90 Days","90+ Days")))) -> 61-90 Days | L21: =IF(I21<=0,"-",IF(J21<=30,"Low",IF(J21<=60,"Low-Medium",IF(J21<=90,"Medium","HIGH RISK")))) -> Medium | M21: =IF(I21<=0,"-",IF(J21<=30,"Normal",IF(J21<=60,"Medium",IF(J21<=90,"Urgent","Immediate Action")))) -> Urgent | N21: Pending | O21: DSO will collect
A22: 21 | B22: Watches | C22: 46045 | D22: SLGCW/1147/25-26 | E22: RAMESH WATCH CO PVT LTD K-INORBIT | F22: 60364 | G22: 46090 | H22: 0 | I22: =MAX(0,F22-H22) -> 60364 | J22: =IF(G22="",0,MAX(0,TODAY()-G22)) -> 74 | K22: =IF(I22<=0,"Current",IF(J22<=30,"0-30 Days",IF(J22<=60,"31-60 Days",IF(J22<=90,"61-90 Days","90+ Days")))) -> 61-90 Days | L22: =IF(I22<=0,"-",IF(J22<=30,"Low",IF(J22<=60,"Low-Medium",IF(J22<=90,"Medium","HIGH RISK")))) -> Medium | M22: =IF(I22<=0,"-",IF(J22<=30,"Normal",IF(J22<=60,"Medium",IF(J22<=90,"Urgent","Immediate Action")))) -> Urgent | N22: Pending | O22: DSO will collect
A23: 22 | B23: Watches | C23: 46045 | D23: SLGCW/1149/25-26 | E23: RAMESH WATCH CO PVT LTD K-INORBIT | F23: 30132 | G23: 46090 | H23: 0 | I23: =MAX(0,F23-H23) -> 30132 | J23: =IF(G23="",0,MAX(0,TODAY()-G23)) -> 74 | K23: =IF(I23<=0,"Current",IF(J23<=30,"0-30 Days",IF(J23<=60,"31-60 Days",IF(J23<=90,"61-90 Days","90+ Days")))) -> 61-90 Days | L23: =IF(I23<=0,"-",IF(J23<=30,"Low",IF(J23<=60,"Low-Medium",IF(J23<=90,"Medium","HIGH RISK")))) -> Medium | M23: =IF(I23<=0,"-",IF(J23<=30,"Normal",IF(J23<=60,"Medium",IF(J23<=90,"Urgent","Immediate Action")))) -> Urgent | N23: Pending | O23: DSO will collect
A24: 23 | B24: Watches | C24: 46055 | D24: SLGCW/1188/25-26 | E24: RAMESH WATCH CO PVT LTD K-INORBIT | F24: 304908 | G24: 46100 | H24: 0 | I24: =MAX(0,F24-H24) -> 304908 | J24: =IF(G24="",0,MAX(0,TODAY()-G24)) -> 64 | K24: =IF(I24<=0,"Current",IF(J24<=30,"0-30 Days",IF(J24<=60,"31-60 Days",IF(J24<=90,"61-90 Days","90+ Days")))) -> 61-90 Days | L24: =IF(I24<=0,"-",IF(J24<=30,"Low",IF(J24<=60,"Low-Medium",IF(J24<=90,"Medium","HIGH RISK")))) -> Medium | M24: =IF(I24<=0,"-",IF(J24<=30,"Normal",IF(J24<=60,"Medium",IF(J24<=90,"Urgent","Immediate Action")))) -> Urgent | N24: Pending | O24: DSO will collect
A25: 24 | B25: Watches | C25: 46067 | D25: SLGCW/1226/25-26 | E25: RAMESH WATCH CO PVT LTD K-INORBIT | F25: 51332 | G25: 46112 | H25: 0 | I25: =MAX(0,F25-H25) -> 51332 | J25: =IF(G25="",0,MAX(0,TODAY()-G25)) -> 52 | K25: =IF(I25<=0,"Current",IF(J25<=30,"0-30 Days",IF(J25<=60,"31-60 Days",IF(J25<=90,"61-90 Days","90+ Days")))) -> 31-60 Days | L25: =IF(I25<=0,"-",IF(J25<=30,"Low",IF(J25<=60,"Low-Medium",IF(J25<=90,"Medium","HIGH RISK")))) -> Low-Medium | M25: =IF(I25<=0,"-",IF(J25<=30,"Normal",IF(J25<=60,"Medium",IF(J25<=90,"Urgent","Immediate Action")))) -> Medium | N25: Pending | O25: DSO will collect
A26: 25 | B26: Watches | C26: 46076 | D26: SLGCW/1233/25-26 | E26: RAMESH WATCH CO PVT LTD K-INORBIT | F26: 11979 | G26: 46121 | H26: 0 | I26: =MAX(0,F26-H26) -> 11979 | J26: =IF(G26="",0,MAX(0,TODAY()-G26)) -> 43 | K26: =IF(I26<=0,"Current",IF(J26<=30,"0-30 Days",IF(J26<=60,"31-60 Days",IF(J26<=90,"61-90 Days","90+ Days")))) -> 31-60 Days | L26: =IF(I26<=0,"-",IF(J26<=30,"Low",IF(J26<=60,"Low-Medium",IF(J26<=90,"Medium","HIGH RISK")))) -> Low-Medium | M26: =IF(I26<=0,"-",IF(J26<=30,"Normal",IF(J26<=60,"Medium",IF(J26<=90,"Urgent","Immediate Action")))) -> Medium | N26: Pending | O26: DSO will collect
A27: 26 | B27: Watches | C27: 46076 | D27: SLGCW/1235/25-26 | E27: RAMESH WATCH CO PVT LTD K-INORBIT | F27: 6291 | G27: 46121 | H27: 0 | I27: =MAX(0,F27-H27) -> 6291 | J27: =IF(G27="",0,MAX(0,TODAY()-G27)) -> 43 | K27: =IF(I27<=0,"Current",IF(J27<=30,"0-30 Days",IF(J27<=60,"31-60 Days",IF(J27<=90,"61-90 Days","90+ Days")))) -> 31-60 Days | L27: =IF(I27<=0,"-",IF(J27<=30,"Low",IF(J27<=60,"Low-Medium",IF(J27<=90,"Medium","HIGH RISK")))) -> Low-Medium | M27: =IF(I27<=0,"-",IF(J27<=30,"Normal",IF(J27<=60,"Medium",IF(J27<=90,"Urgent","Immediate Action")))) -> Medium | N27: Pending | O27: DSO will collect
A28: 27 | B28: Watches | C28: 46076 | D28: SLGCW/1236/25-26 | E28: RAMESH WATCH CO PVT LTD K-INORBIT | F28: 7296 | G28: 46121 | H28: 0 | I28: =MAX(0,F28-H28) -> 7296 | J28: =IF(G28="",0,MAX(0,TODAY()-G28)) -> 43 | K28: =IF(I28<=0,"Current",IF(J28<=30,"0-30 Days",IF(J28<=60,"31-60 Days",IF(J28<=90,"61-90 Days","90+ Days")))) -> 31-60 Days | L28: =IF(I28<=0,"-",IF(J28<=30,"Low",IF(J28<=60,"Low-Medium",IF(J28<=90,"Medium","HIGH RISK")))) -> Low-Medium | M28: =IF(I28<=0,"-",IF(J28<=30,"Normal",IF(J28<=60,"Medium",IF(J28<=90,"Urgent","Immediate Action")))) -> Medium | N28: Pending | O28: DSO will collect
A29: 28 | B29: Watches | C29: 46090 | D29: SLGCW/1247/25-26 | E29: RAMESH WATCH CO PVT LTD K-INORBIT | F29: 17417 | G29: 46135 | H29: 0 | I29: =MAX(0,F29-H29) -> 17417 | J29: =IF(G29="",0,MAX(0,TODAY()-G29)) -> 29 | K29: =IF(I29<=0,"Current",IF(J29<=30,"0-30 Days",IF(J29<=60,"31-60 Days",IF(J29<=90,"61-90 Days","90+ Days")))) -> 0-30 Days | L29: =IF(I29<=0,"-",IF(J29<=30,"Low",IF(J29<=60,"Low-Medium",IF(J29<=90,"Medium","HIGH RISK")))) -> Low | M29: =IF(I29<=0,"-",IF(J29<=30,"Normal",IF(J29<=60,"Medium",IF(J29<=90,"Urgent","Immediate Action")))) -> Normal | N29: Pending | O29: DSO will collect
... A54: 53 | B54: Watches | C54: 46142 | D54: SLGCW/41/26-27 | E54: Siddi Times & Electronics | F54: 149682 | G54: 46143 | H54: 149682 | I54: =MAX(0,F54-H54) -> 0 | J54: =IF(G54="",0,MAX(0,TODAY()-G54)) -> 21 | K54: =IF(I54<=0,"Current",IF(J54<=30,"0-30 Days",IF(J54<=60,"31-60 Days",IF(J54<=90,"61-90 Days","90+ Days")))) -> Current | L54: =IF(I54<=0,"-",IF(J54<=30,"Low",IF(J54<=60,"Low-Medium",IF(J54<=90,"Medium","HIGH RISK")))) -> - | M54: =IF(I54<=0,"-",IF(J54<=30,"Normal",IF(J54<=60,"Medium",IF(J54<=90,"Urgent","Immediate Action")))) -> - | N54: Paid | O54: Send DSO tommorrow morning
A55: 54 | B55: Watches | C55: 46102 | D55: SLGCW/1263/25-26 | E55: SS WATCHES AND SUNGLASSES | F55: 12806 | G55: 46102 | H55: 0 | I55: =MAX(0,F55-H55) -> 12806 | J55: =IF(G55="",0,MAX(0,TODAY()-G55)) -> 62 | K55: =IF(I55<=0,"Current",IF(J55<=30,"0-30 Days",IF(J55<=60,"31-60 Days",IF(J55<=90,"61-90 Days","90+ Days")))) -> 61-90 Days | L55: =IF(I55<=0,"-",IF(J55<=30,"Low",IF(J55<=60,"Low-Medium",IF(J55<=90,"Medium","HIGH RISK")))) -> Medium | M55: =IF(I55<=0,"-",IF(J55<=30,"Normal",IF(J55<=60,"Medium",IF(J55<=90,"Urgent","Immediate Action")))) -> Urgent | N55: Pending
A56: 55 | B56: Watches | C56: 46137 | D56: SLGCW/18/26-27 | E56: Sunny Watch | F56: 111599 | G56: 46138 | H56: 0 | I56: =MAX(0,F56-H56) -> 111599 | J56: =IF(G56="",0,MAX(0,TODAY()-G56)) -> 26 | K56: =IF(I56<=0,"Current",IF(J56<=30,"0-30 Days",IF(J56<=60,"31-60 Days",IF(J56<=90,"61-90 Days","90+ Days")))) -> 0-30 Days | L56: =IF(I56<=0,"-",IF(J56<=30,"Low",IF(J56<=60,"Low-Medium",IF(J56<=90,"Medium","HIGH RISK")))) -> Low | M56: =IF(I56<=0,"-",IF(J56<=30,"Normal",IF(J56<=60,"Medium",IF(J56<=90,"Urgent","Immediate Action")))) -> Normal | N56: Pending | O56: Not Responding
A57: 56 | B57: Watches | C57: 46144 | D57: SLGCW/56/26-27 | E57: Sunny Watch | F57: 20227 | G57: 46169 | H57: 0 | I57: =MAX(0,F57-H57) -> 20227 | J57: =IF(G57="",0,MAX(0,TODAY()-G57)) -> 0 | K57: =IF(I57<=0,"Current",IF(J57<=30,"0-30 Days",IF(J57<=60,"31-60 Days",IF(J57<=90,"61-90 Days","90+ Days")))) -> 0-30 Days | L57: =IF(I57<=0,"-",IF(J57<=30,"Low",IF(J57<=60,"Low-Medium",IF(J57<=90,"Medium","HIGH RISK")))) -> Low | M57: =IF(I57<=0,"-",IF(J57<=30,"Normal",IF(J57<=60,"Medium",IF(J57<=90,"Urgent","Immediate Action")))) -> Normal | N57: Pending
A58: 57 | B58: Watches | C58: 46137 | D58: SLGCW/20/26-27 | E58: THE TIMES | F58: 70357 | G58: 46137 | H58: 0 | I58: =MAX(0,F58-H58) -> 70357 | J58: =IF(G58="",0,MAX(0,TODAY()-G58)) -> 27 | K58: =IF(I58<=0,"Current",IF(J58<=30,"0-30 Days",IF(J58<=60,"31-60 Days",IF(J58<=90,"61-90 Days","90+ Days")))) -> 0-30 Days | L58: =IF(I58<=0,"-",IF(J58<=30,"Low",IF(J58<=60,"Low-Medium",IF(J58<=90,"Medium","HIGH RISK")))) -> Low | M58: =IF(I58<=0,"-",IF(J58<=30,"Normal",IF(J58<=60,"Medium",IF(J58<=90,"Urgent","Immediate Action")))) -> Normal | N58: Pending | O58: Next Week (Market Down)
A59: 58 | B59: Praveen | C59: 46095 | D59: C-SLG/2384/25-26 | E59: AMBIKA STATIONERY | F59: 8075 | G59: 46120 | H59: 0 | I59: =MAX(0,F59-H59) -> 8075 | J59: =IF(G59="",0,MAX(0,TODAY()-G59)) -> 44 | K59: =IF(I59<=0,"Current",IF(J59<=30,"0-30 Days",IF(J59<=60,"31-60 Days",IF(J59<=90,"61-90 Days","90+ Days")))) -> 31-60 Days | L59: =IF(I59<=0,"-",IF(J59<=30,"Low",IF(J59<=60,"Low-Medium",IF(J59<=90,"Medium","HIGH RISK")))) -> Low-Medium | M59: =IF(I59<=0,"-",IF(J59<=30,"Normal",IF(J59<=60,"Medium",IF(J59<=90,"Urgent","Immediate Action")))) -> Medium | N59: Pending | O59: Number Busy
A60: 59 | B60: Praveen | C60: 45996 | D60: C-SLG/1844/25-26 | E60: BEST ENTERPRISES | F60: 30511 | G60: 46021 | H60: 0 | I60: =MAX(0,F60-H60) -> 30511 | J60: =IF(G60="",0,MAX(0,TODAY()-G60)) -> 143 | K60: =IF(I60<=0,"Current",IF(J60<=30,"0-30 Days",IF(J60<=60,"31-60 Days",IF(J60<=90,"61-90 Days","90+ Days")))) -> 90+ Days | L60: =IF(I60<=0,"-",IF(J60<=30,"Low",IF(J60<=60,"Low-Medium",IF(J60<=90,"Medium","HIGH RISK")))) -> HIGH RISK | M60: =IF(I60<=0,"-",IF(J60<=30,"Normal",IF(J60<=60,"Medium",IF(J60<=90,"Urgent","Immediate Action")))) -> Immediate Action | N60: Pending | O60: Customer Out of Station - Month end he will Pay
A61: 60 | B61: Praveen | C61: 46105 | D61: C-SLG/2429/25-26 | E61: Bhavani Stationery and Gift | F61: 1186 | G61: 46130 | H61: 0 | I61: =MAX(0,F61-H61) -> 1186 | J61: =IF(G61="",0,MAX(0,TODAY()-G61)) -> 34 | K61: =IF(I61<=0,"Current",IF(J61<=30,"0-30 Days",IF(J61<=60,"31-60 Days",IF(J61<=90,"61-90 Days","90+ Days")))) -> 31-60 Days | L61: =IF(I61<=0,"-",IF(J61<=30,"Low",IF(J61<=60,"Low-Medium",IF(J61<=90,"Medium","HIGH RISK")))) -> Low-Medium | M61: =IF(I61<=0,"-",IF(J61<=30,"Normal",IF(J61<=60,"Medium",IF(J61<=90,"Urgent","Immediate Action")))) -> Medium | N61: Pending
A62: 61 | B62: Praveen | C62: 46156 | D62: C-SLG/0125/26-27 | E62: Bhavani Stationery and Gift | F62: 2941 | G62: 46181 | H62: 0 | I62: =MAX(0,F62-H62) -> 2941 | J62: =IF(G62="",0,MAX(0,TODAY()-G62)) -> 0 | K62: =IF(I62<=0,"Current",IF(J62<=30,"0-30 Days",IF(J62<=60,"31-60 Days",IF(J62<=90,"61-90 Days","90+ Days")))) -> 0-30 Days | L62: =IF(I62<=0,"-",IF(J62<=30,"Low",IF(J62<=60,"Low-Medium",IF(J62<=90,"Medium","HIGH RISK")))) -> Low | M62: =IF(I62<=0,"-",IF(J62<=30,"Normal",IF(J62<=60,"Medium",IF(J62<=90,"Urgent","Immediate Action")))) -> Normal | N62: Pending
A63: 62 | B63: Praveen | C63: 46105 | D63: C-SLG/2427/25-26 | E63: Dachapally Book Centre | F63: 5152 | G63: 46130 | H63: 0 | I63: =MAX(0,F63-H63) -> 5152 | J63: =IF(G63="",0,MAX(0,TODAY()-G63)) -> 34 | K63: =IF(I63<=0,"Current",IF(J63<=30,"0-30 Days",IF(J63<=60,"31-60 Days",IF(J63<=90,"61-90 Days","90+ Days")))) -> 31-60 Days | L63: =IF(I63<=0,"-",IF(J63<=30,"Low",IF(J63<=60,"Low-Medium",IF(J63<=90,"Medium","HIGH RISK")))) -> Low-Medium | M63: =IF(I63<=0,"-",IF(J63<=30,"Normal",IF(J63<=60,"Medium",IF(J63<=90,"Urgent","Immediate Action")))) -> Medium | N63: Pending | O63: No Number available - Send DSO
A64: 63 | B64: Praveen | C64: 45975 | D64: C-SLG/1655/25-26 | E64: Deccan Book Depot and Stationery | F64: 2900 | G64: 46000 | H64: 0 | I64: =MAX(0,F64-H64) -> 2900 | J64: =IF(G64="",0,MAX(0,TODAY()-G64)) -> 164 | K64: =IF(I64<=0,"Current",IF(J64<=30,"0-30 Days",IF(J64<=60,"31-60 Days",IF(J64<=90,"61-90 Days","90+ Days")))) -> 90+ Days | L64: =IF(I64<=0,"-",IF(J64<=30,"Low",IF(J64<=60,"Low-Medium",IF(J64<=90,"Medium","HIGH RISK")))) -> HIGH RISK | M64: =IF(I64<=0,"-",IF(J64<=30,"Normal",IF(J64<=60,"Medium",IF(J64<=90,"Urgent","Immediate Action")))) -> Immediate Action | N64: Pending | O64: Send DSO with Sign Copies
...

Sheet CALLING_LIST
A1: Collection Calling List (Overdue > 30 Days)
A2: Generated: 21-May-2026
A4: S.No | B4: Customer Name | C4: Invoice No | D4: Invoice Date | E4: Due Date | F4: Outstanding Amount | G4: Days Overdue | H4: Aging Bucket | I4: Risk Level | J4: Previous Remarks | K4: Call Status | L4: New Follow-up Notes | M4: Next Follow-up Date
A5: 1 | B5: =IF(MASTER_AR_REPORT!E3="","",MASTER_AR_REPORT!E3) -> KHALEEL WATCH CO. | C5: =IF(MASTER_AR_REPORT!D3="","",MASTER_AR_REPORT!D3) -> SLGCW/1077/24-25 | D5: =MASTER_AR_REPORT!C3 -> 45716 | E5: =MASTER_AR_REPORT!G3 -> 45716 | F5: =MASTER_AR_REPORT!I3 -> 159.67 | G5: =MASTER_AR_REPORT!J3 -> 448 | H5: =MASTER_AR_REPORT!K3 -> 90+ Days | I5: =MASTER_AR_REPORT!L3 -> HIGH RISK | J5: =MASTER_AR_REPORT!M3 -> Immediate Action | K5: Pending
A6: 2 | B6: =IF(MASTER_AR_REPORT!E4="","",MASTER_AR_REPORT!E4) -> KHALEEL WATCH CO. | C6: =IF(MASTER_AR_REPORT!D4="","",MASTER_AR_REPORT!D4) -> SLGCW/1035/25-26 | D6: =MASTER_AR_REPORT!C4 -> 46013 | E6: =MASTER_AR_REPORT!G4 -> 46043 | F6: =MASTER_AR_REPORT!I4 -> 383 | G6: =MASTER_AR_REPORT!J4 -> 121 | H6: =MASTER_AR_REPORT!K4 -> 90+ Days | I6: =MASTER_AR_REPORT!L4 -> HIGH RISK | J6: =MASTER_AR_REPORT!M4 -> Immediate Action | K6: Pending
A7: 3 | B7: =IF(MASTER_AR_REPORT!E5="","",MASTER_AR_REPORT!E5) -> KISHORE WATCH CO | C7: =IF(MASTER_AR_REPORT!D5="","",MASTER_AR_REPORT!D5) -> SLGCW/969/25-26 | D7: =MASTER_AR_REPORT!C5 -> 45996 | E7: =MASTER_AR_REPORT!G5 -> 46041 | F7: =MASTER_AR_REPORT!I5 -> 2852 | G7: =MASTER_AR_REPORT!J5 -> 123 | H7: =MASTER_AR_REPORT!K5 -> 90+ Days | I7: =MASTER_AR_REPORT!L5 -> HIGH RISK | J7: =MASTER_AR_REPORT!M5 -> Immediate Action | K7: Pending
A8: 4 | B8: =IF(MASTER_AR_REPORT!E15="","",MASTER_AR_REPORT!E15) -> MILAP GENERAL STORES | C8: =IF(MASTER_AR_REPORT!D15="","",MASTER_AR_REPORT!D15) -> SLGCW/1043/24-25 | D8: =MASTER_AR_REPORT!C15 -> 45705 | E8: =MASTER_AR_REPORT!G15 -> 45705 | F8: =MASTER_AR_REPORT!I15 -> 560 | G8: =MASTER_AR_REPORT!J15 -> 459 | H8: =MASTER_AR_REPORT!K15 -> 90+ Days | I8: =MASTER_AR_REPORT!L15 -> HIGH RISK | J8: =MASTER_AR_REPORT!M15 -> Immediate Action | K8: Pending
A9: 5 | B9: =IF(MASTER_AR_REPORT!E16="","",MASTER_AR_REPORT!E16) -> MILAP GENERAL STORES | C9: =IF(MASTER_AR_REPORT!D16="","",MASTER_AR_REPORT!D16) -> SLGCW/1061/24-25 | D9: =MASTER_AR_REPORT!C16 -> 45708 | E9: =MASTER_AR_REPORT!G16 -> 45708 | F9: =MASTER_AR_REPORT!I16 -> 103.36 | G9: =MASTER_AR_REPORT!J16 -> 456 | H9: =MASTER_AR_REPORT!K16 -> 90+ Days | I9: =MASTER_AR_REPORT!L16 -> HIGH RISK | J9: =MASTER_AR_REPORT!M16 -> Immediate Action | K9: Pending
A10: 6 | B10: =IF(MASTER_AR_REPORT!E19="","",MASTER_AR_REPORT!E19) -> RAMESH WATCH CO PVT LTD K-INORBIT | C10: =IF(MASTER_AR_REPORT!D19="","",MASTER_AR_REPORT!D19) -> SLGCW/898/24-25 | D10: =MASTER_AR_REPORT!C19 -> 45667 | E10: =MASTER_AR_REPORT!G19 -> 45667 | F10: =MASTER_AR_REPORT!I19 -> 92000 | G10: =MASTER_AR_REPORT!J19 -> 497 | H10: =MASTER_AR_REPORT!K19 -> 90+ Days | I10: =MASTER_AR_REPORT!L19 -> HIGH RISK | J10: =MASTER_AR_REPORT!M19 -> Immediate Action | K10: Pending
A11: 7 | B11: =IF(MASTER_AR_REPORT!E20="","",MASTER_AR_REPORT!E20) -> RAMESH WATCH CO PVT LTD K-INORBIT | C11: =IF(MASTER_AR_REPORT!D20="","",MASTER_AR_REPORT!D20) -> SLGCW/1138/25-26 | D11: =MASTER_AR_REPORT!C20 -> 46044 | E11: =MASTER_AR_REPORT!G20 -> 46089 | F11: =MASTER_AR_REPORT!I20 -> 74393 | G11: =MASTER_AR_REPORT!J20 -> 75 | H11: =MASTER_AR_REPORT!K20 -> 61-90 Days | I11: =MASTER_AR_REPORT!L20 -> Medium | J11: =MASTER_AR_REPORT!M20 -> Urgent | K11: Pending
A12: 8 | B12: =IF(MASTER_AR_REPORT!E21="","",MASTER_AR_REPORT!E21) -> RAMESH WATCH CO PVT LTD K-INORBIT | C12: =IF(MASTER_AR_REPORT!D21="","",MASTER_AR_REPORT!D21) -> SLGCW/1150/25-26 | D12: =MASTER_AR_REPORT!C21 -> 46045 | E12: =MASTER_AR_REPORT!G21 -> 46090 | F12: =MASTER_AR_REPORT!I21 -> 263334 | G12: =MASTER_AR_REPORT!J21 -> 74 | H12: =MASTER_AR_REPORT!K21 -> 61-90 Days | I12: =MASTER_AR_REPORT!L21 -> Medium | J12: =MASTER_AR_REPORT!M21 -> Urgent | K12: Pending
A13: 9 | B13: =IF(MASTER_AR_REPORT!E22="","",MASTER_AR_REPORT!E22) -> RAMESH WATCH CO PVT LTD K-INORBIT | C13: =IF(MASTER_AR_REPORT!D22="","",MASTER_AR_REPORT!D22) -> SLGCW/1147/25-26 | D13: =MASTER_AR_REPORT!C22 -> 46045 | E13: =MASTER_AR_REPORT!G22 -> 46090 | F13: =MASTER_AR_REPORT!I22 -> 60364 | G13: =MASTER_AR_REPORT!J22 -> 74 | H13: =MASTER_AR_REPORT!K22 -> 61-90 Days | I13: =MASTER_AR_REPORT!L22 -> Medium | J13: =MASTER_AR_REPORT!M22 -> Urgent | K13: Pending
A14: 10 | B14: =IF(MASTER_AR_REPORT!E23="","",MASTER_AR_REPORT!E23) -> RAMESH WATCH CO PVT LTD K-INORBIT | C14: =IF(MASTER_AR_REPORT!D23="","",MASTER_AR_REPORT!D23) -> SLGCW/1149/25-26 | D14: =MASTER_AR_REPORT!C23 -> 46045 | E14: =MASTER_AR_REPORT!G23 -> 46090 | F14: =MASTER_AR_REPORT!I23 -> 30132 | G14: =MASTER_AR_REPORT!J23 -> 74 | H14: =MASTER_AR_REPORT!K23 -> 61-90 Days | I14: =MASTER_AR_REPORT!L23 -> Medium | J14: =MASTER_AR_REPORT!M23 -> Urgent | K14: Pending
A15: 11 | B15: =IF(MASTER_AR_REPORT!E24="","",MASTER_AR_REPORT!E24) -> RAMESH WATCH CO PVT LTD K-INORBIT | C15: =IF(MASTER_AR_REPORT!D24="","",MASTER_AR_REPORT!D24) -> SLGCW/1188/25-26 | D15: =MASTER_AR_REPORT!C24 -> 46055 | E15: =MASTER_AR_REPORT!G24 -> 46100 | F15: =MASTER_AR_REPORT!I24 -> 304908 | G15: =MASTER_AR_REPORT!J24 -> 64 | H15: =MASTER_AR_REPORT!K24 -> 61-90 Days | I15: =MASTER_AR_REPORT!L24 -> Medium | J15: =MASTER_AR_REPORT!M24 -> Urgent | K15: Pending
A16: 12 | B16: =IF(MASTER_AR_REPORT!E25="","",MASTER_AR_REPORT!E25) -> RAMESH WATCH CO PVT LTD K-INORBIT | C16: =IF(MASTER_AR_REPORT!D25="","",MASTER_AR_REPORT!D25) -> SLGCW/1226/25-26 | D16: =MASTER_AR_REPORT!C25 -> 46067 | E16: =MASTER_AR_REPORT!G25 -> 46112 | F16: =MASTER_AR_REPORT!I25 -> 51332 | G16: =MASTER_AR_REPORT!J25 -> 52 | H16: =MASTER_AR_REPORT!K25 -> 31-60 Days | I16: =MASTER_AR_REPORT!L25 -> Low-Medium | J16: =MASTER_AR_REPORT!M25 -> Medium | K16: Pending
A17: 13 | B17: =IF(MASTER_AR_REPORT!E26="","",MASTER_AR_REPORT!E26) -> RAMESH WATCH CO PVT LTD K-INORBIT | C17: =IF(MASTER_AR_REPORT!D26="","",MASTER_AR_REPORT!D26) -> SLGCW/1233/25-26 | D17: =MASTER_AR_REPORT!C26 -> 46076 | E17: =MASTER_AR_REPORT!G26 -> 46121 | F17: =MASTER_AR_REPORT!I26 -> 11979 | G17: =MASTER_AR_REPORT!J26 -> 43 | H17: =MASTER_AR_REPORT!K26 -> 31-60 Days | I17: =MASTER_AR_REPORT!L26 -> Low-Medium | J17: =MASTER_AR_REPORT!M26 -> Medium | K17: Pending
A18: 14 | B18: =IF(MASTER_AR_REPORT!E27="","",MASTER_AR_REPORT!E27) -> RAMESH WATCH CO PVT LTD K-INORBIT | C18: =IF(MASTER_AR_REPORT!D27="","",MASTER_AR_REPORT!D27) -> SLGCW/1235/25-26 | D18: =MASTER_AR_REPORT!C27 -> 46076 | E18: =MASTER_AR_REPORT!G27 -> 46121 | F18: =MASTER_AR_REPORT!I27 -> 6291 | G18: =MASTER_AR_REPORT!J27 -> 43 | H18: =MASTER_AR_REPORT!K27 -> 31-60 Days | I18: =MASTER_AR_REPORT!L27 -> Low-Medium | J18: =MASTER_AR_REPORT!M27 -> Medium | K18: Pending
A19: 15 | B19: =IF(MASTER_AR_REPORT!E28="","",MASTER_AR_REPORT!E28) -> RAMESH WATCH CO PVT LTD K-INORBIT | C19: =IF(MASTER_AR_REPORT!D28="","",MASTER_AR_REPORT!D28) -> SLGCW/1236/25-26 | D19: =MASTER_AR_REPORT!C28 -> 46076 | E19: =MASTER_AR_REPORT!G28 -> 46121 | F19: =MASTER_AR_REPORT!I28 -> 7296 | G19: =MASTER_AR_REPORT!J28 -> 43 | H19: =MASTER_AR_REPORT!K28 -> 31-60 Days | I19: =MASTER_AR_REPORT!L28 -> Low-Medium | J19: =MASTER_AR_REPORT!M28 -> Medium | K19: Pending
A20: 16 | B20: =IF(MASTER_AR_REPORT!E52="","",MASTER_AR_REPORT!E52) -> RAVINDRA WATCH REPAIR | C20: =IF(MASTER_AR_REPORT!D52="","",MASTER_AR_REPORT!D52) -> SLGCW/969/24-25 | D20: =MASTER_AR_REPORT!C52 -> 45682 | E20: =MASTER_AR_REPORT!G52 -> 45682 | F20: =MASTER_AR_REPORT!I52 -> 271 | G20: =MASTER_AR_REPORT!J52 -> 482 | H20: =MASTER_AR_REPORT!K52 -> 90+ Days | I20: =MASTER_AR_REPORT!L52 -> HIGH RISK | J20: =MASTER_AR_REPORT!M52 -> Immediate Action | K20: Pending
A21: 17 | B21: =IF(MASTER_AR_REPORT!E53="","",MASTER_AR_REPORT!E53) -> RAVINDRA WATCH REPAIR | C21: =IF(MASTER_AR_REPORT!D53="","",MASTER_AR_REPORT!D53) -> SLGCW/768/25-26 | D21: =MASTER_AR_REPORT!C53 -> 45951 | E21: =MASTER_AR_REPORT!G53 -> 45952 | F21: =MASTER_AR_REPORT!I53 -> 272 | G21: =MASTER_AR_REPORT!J53 -> 212 | H21: =MASTER_AR_REPORT!K53 -> 90+ Days | I21: =MASTER_AR_REPORT!L53 -> HIGH RISK | J21: =MASTER_AR_REPORT!M53 -> Immediate Action | K21: Pending
A22: 18 | B22: =IF(MASTER_AR_REPORT!E55="","",MASTER_AR_REPORT!E55) -> SS WATCHES AND SUNGLASSES | C22: =IF(MASTER_AR_REPORT!D55="","",MASTER_AR_REPORT!D55) -> SLGCW/1263/25-26 | D22: =MASTER_AR_REPORT!C55 -> 46102 | E22: =MASTER_AR_REPORT!G55 -> 46102 | F22: =MASTER_AR_REPORT!I55 -> 12806 | G22: =MASTER_AR_REPORT!J55 -> 62 | H22: =MASTER_AR_REPORT!K55 -> 61-90 Days | I22: =MASTER_AR_REPORT!L55 -> Medium | J22: =MASTER_AR_REPORT!M55 -> Urgent | K22: Pending
A23: 19 | B23: =IF(MASTER_AR_REPORT!E59="","",MASTER_AR_REPORT!E59) -> AMBIKA STATIONERY | C23: =IF(MASTER_AR_REPORT!D59="","",MASTER_AR_REPORT!D59) -> C-SLG/2384/25-26 | D23: =MASTER_AR_REPORT!C59 -> 46095 | E23: =MASTER_AR_REPORT!G59 -> 46120 | F23: =MASTER_AR_REPORT!I59 -> 8075 | G23: =MASTER_AR_REPORT!J59 -> 44 | H23: =MASTER_AR_REPORT!K59 -> 31-60 Days | I23: =MASTER_AR_REPORT!L59 -> Low-Medium | J23: =MASTER_AR_REPORT!M59 -> Medium | K23: Pending
A24: 20 | B24: =IF(MASTER_AR_REPORT!E60="","",MASTER_AR_REPORT!E60) -> BEST ENTERPRISES | C24: =IF(MASTER_AR_REPORT!D60="","",MASTER_AR_REPORT!D60) -> C-SLG/1844/25-26 | D24: =MASTER_AR_REPORT!C60 -> 45996 | E24: =MASTER_AR_REPORT!G60 -> 46021 | F24: =MASTER_AR_REPORT!I60 -> 30511 | G24: =MASTER_AR_REPORT!J60 -> 143 | H24: =MASTER_AR_REPORT!K60 -> 90+ Days | I24: =MASTER_AR_REPORT!L60 -> HIGH RISK | J24: =MASTER_AR_REPORT!M60 -> Immediate Action | K24: Pending
A25: 21 | B25: =IF(MASTER_AR_REPORT!E61="","",MASTER_AR_REPORT!E61) -> Bhavani Stationery and Gift | C25: =IF(MASTER_AR_REPORT!D61="","",MASTER_AR_REPORT!D61) -> C-SLG/2429/25-26 | D25: =MASTER_AR_REPORT!C61 -> 46105 | E25: =MASTER_AR_REPORT!G61 -> 46130 | F25: =MASTER_AR_REPORT!I61 -> 1186 | G25: =MASTER_AR_REPORT!J61 -> 34 | H25: =MASTER_AR_REPORT!K61 -> 31-60 Days | I25: =MASTER_AR_REPORT!L61 -> Low-Medium | J25: =MASTER_AR_REPORT!M61 -> Medium | K25: Pending
A26: 22 | B26: =IF(MASTER_AR_REPORT!E63="","",MASTER_AR_REPORT!E63) -> Dachapally Book Centre | C26: =IF(MASTER_AR_REPORT!D63="","",MASTER_AR_REPORT!D63) -> C-SLG/2427/25-26 | D26: =MASTER_AR_REPORT!C63 -> 46105 | E26: =MASTER_AR_REPORT!G63 -> 46130 | F26: =MASTER_AR_REPORT!I63 -> 5152 | G26: =MASTER_AR_REPORT!J63 -> 34 | H26: =MASTER_AR_REPORT!K63 -> 31-60 Days | I26: =MASTER_AR_REPORT!L63 -> Low-Medium | J26: =MASTER_AR_REPORT!M63 -> Medium | K26: Pending
A27: 23 | B27: =IF(MASTER_AR_REPORT!E64="","",MASTER_AR_REPORT!E64) -> Deccan Book Depot and Stationery | C27: =IF(MASTER_AR_REPORT!D64="","",MASTER_AR_REPORT!D64) -> C-SLG/1655/25-26 | D27: =MASTER_AR_REPORT!C64 -> 45975 | E27: =MASTER_AR_REPORT!G64 -> 46000 | F27: =MASTER_AR_REPORT!I64 -> 2900 | G27: =MASTER_AR_REPORT!J64 -> 164 | H27: =MASTER_AR_REPORT!K64 -> 90+ Days | I27: =MASTER_AR_REPORT!L64 -> HIGH RISK | J27: =MASTER_AR_REPORT!M64 -> Immediate Action | K27: Pending
A28: 24 | B28: =IF(MASTER_AR_REPORT!E65="","",MASTER_AR_REPORT!E65) -> Deccan Book Depot and Stationery | C28: =IF(MASTER_AR_REPORT!D65="","",MASTER_AR_REPORT!D65) -> C-SLG/2235/25-26 | D28: =MASTER_AR_REPORT!C65 -> 46069 | E28: =MASTER_AR_REPORT!G65 -> 46094 | F28: =MASTER_AR_REPORT!I65 -> 2044 | G28: =MASTER_AR_REPORT!J65 -> 70 | H28: =MASTER_AR_REPORT!K65 -> 61-90 Days | I28: =MASTER_AR_REPORT!L65 -> Medium | J28: =MASTER_AR_REPORT!M65 -> Urgent | K28: Pending
A29: 25 | B29: =IF(MASTER_AR_REPORT!E66="","",MASTER_AR_REPORT!E66) -> Dilip Super Market (Manikonda) | C29: =IF(MASTER_AR_REPORT!D66="","",MASTER_AR_REPORT!D66) -> C-SLG/2344/25-26 | D29: =MASTER_AR_REPORT!C66 -> 46088 | E29: =MASTER_AR_REPORT!G66 -> 46113 | F29: =MASTER_AR_REPORT!I66 -> 2472 | G29: =MASTER_AR_REPORT!J66 -> 51 | H29: =MASTER_AR_REPORT!K66 -> 31-60 Days | I29: =MASTER_AR_REPORT!L66 -> Low-Medium | J29: =MASTER_AR_REPORT!M66 -> Medium | K29: Pending
A30: 26 | B30: =IF(MASTER_AR_REPORT!E67="","",MASTER_AR_REPORT!E67) -> Ever Green Book Centre | C30: =IF(MASTER_AR_REPORT!D67="","",MASTER_AR_REPORT!D67) -> C-SLG/2432/25-25 | D30: =MASTER_AR_REPORT!C67 -> 46105 | E30: =MASTER_AR_REPORT!G67 -> 46130 | F30: =MASTER_AR_REPORT!I67 -> 381 | G30: =MASTER_AR_REPORT!J67 -> 34 | H30: =MASTER_AR_REPORT!K67 -> 31-60 Days | I30: =MASTER_AR_REPORT!L67 -> Low-Medium | J30: =MASTER_AR_REPORT!M67 -> Medium | K30: Pending
A31: 27 | B31: =IF(MASTER_AR_REPORT!E69="","",MASTER_AR_REPORT!E69) -> GLOBAL STATIONERY | C31: =IF(MASTER_AR_REPORT!D69="","",MASTER_AR_REPORT!D69) -> C-SLG/2419/25-26 | D31: =MASTER_AR_REPORT!C69 -> 46104 | E31: =MASTER_AR_REPORT!G69 -> 46129 | F31: =MASTER_AR_REPORT!I69 -> 2 | G31: =MASTER_AR_REPORT!J69 -> 35 | H31: =MASTER_AR_REPORT!K69 -> 31-60 Days | I31: =MASTER_AR_REPORT!L69 -> Low-Medium | J31: =MASTER_AR_REPORT!M69 -> Medium | K31: Pending
A32: 28 | B32: =IF(MASTER_AR_REPORT!E70="","",MASTER_AR_REPORT!E70) -> GS Enterprises | C32: =IF(MASTER_AR_REPORT!D70="","",MASTER_AR_REPORT!D70) -> C-SLG/2385/25-26 | D32: =MASTER_AR_REPORT!C70 -> 46095 | E32: =MASTER_AR_REPORT!G70 -> 46120 | F32: =MASTER_AR_REPORT!I70 -> 2561 | G32: =MASTER_AR_REPORT!J70 -> 44 | H32: =MASTER_AR_REPORT!K70 -> 31-60 Days | I32: =MASTER_AR_REPORT!L70 -> Low-Medium | J32: =MASTER_AR_REPORT!M70 -> Medium | K32: Pending
A33: 29 | B33: =IF(MASTER_AR_REPORT!E71="","",MASTER_AR_REPORT!E71) -> Hasti Stationery Mart (Madhapur) | C33: =IF(MASTER_AR_REPORT!D71="","",MASTER_AR_REPORT!D71) -> C-SLG/2351/25-26 | D33: =MASTER_AR_REPORT!C71 -> 46090 | E33: =MASTER_AR_REPORT!G71 -> 46115 | F33: =MASTER_AR_REPORT!I71 -> 4181 | G33: =MASTER_AR_REPORT!J71 -> 49 | H33: =MASTER_AR_REPORT!K71 -> 31-60 Days | I33: =MASTER_AR_REPORT!L71 -> Low-Medium | J33: =MASTER_AR_REPORT!M71 -> Medium | K33: Pending
A34: 30 | B34: =IF(MASTER_AR_REPORT!E72="","",MASTER_AR_REPORT!E72) -> Hasti Stationery Mart (Madhapur) | C34: =IF(MASTER_AR_REPORT!D72="","",MASTER_AR_REPORT!D72) -> C-SLG/2443/25-26 | D34: =MASTER_AR_REPORT!C72 -> 46107 | E34: =MASTER_AR_REPORT!G72 -> 46132 | F34: =MASTER_AR_REPORT!I72 -> 947 | G34: =MASTER_AR_REPORT!J72 -> 32 | H34: =MASTER_AR_REPORT!K72 -> 31-60 Days | I34: =MASTER_AR_REPORT!L72 -> Low-Medium | J34: =MASTER_AR_REPORT!M72 -> Medium | K34: Pending
A35: 31 | B35: =IF(MASTER_AR_REPORT!E73="","",MASTER_AR_REPORT!E73) -> Hyderabad Communications | C35: =IF(MASTER_AR_REPORT!D73="","",MASTER_AR_REPORT!D73) -> C-SLG/631/24-25 | D35: =MASTER_AR_REPORT!C73 -> 45489 | E35: =MASTER_AR_REPORT!G73 -> 45514 | F35: =MASTER_AR_REPORT!I73 -> 34687 | G35: =MASTER_AR_REPORT!J73 -> 650 | H35: =MASTER_AR_REPORT!K73 -> 90+ Days | I35: =MASTER_AR_REPORT!L73 -> HIGH RISK | J35: =MASTER_AR_REPORT!M73 -> Immediate Action | K35: Pending
A36: 32 | B36: =IF(MASTER_AR_REPORT!E74="","",MASTER_AR_REPORT!E74) -> Hyderabad Communications | C36: =IF(MASTER_AR_REPORT!D74="","",MASTER_AR_REPORT!D74) -> C-SLG/800/24-25 | D36: =MASTER_AR_REPORT!C74 -> 45510 | E36: =MASTER_AR_REPORT!G74 -> 45535 | F36: =MASTER_AR_REPORT!I74 -> 596 | G36: =MASTER_AR_REPORT!J74 -> 629 | H36: =MASTER_AR_REPORT!K74 -> 90+ Days | I36: =MASTER_AR_REPORT!L74 -> HIGH RISK | J36: =MASTER_AR_REPORT!M74 -> Immediate Action | K36: Pending
A37: 33 | B37: =IF(MASTER_AR_REPORT!E75="","",MASTER_AR_REPORT!E75) -> Hyderabad Communications | C37: =IF(MASTER_AR_REPORT!D75="","",MASTER_AR_REPORT!D75) -> C-SLG/979/24-25 | D37: =MASTER_AR_REPORT!C75 -> 45533 | E37: =MASTER_AR_REPORT!G75 -> 45558 | F37: =MASTER_AR_REPORT!I75 -> 24001 | G37: =MASTER_AR_REPORT!J75 -> 606 | H37: =MASTER_AR_REPORT!K75 -> 90+ Days | I37: =MASTER_AR_REPORT!L75 -> HIGH RISK | J37: =MASTER_AR_REPORT!M75 -> Immediate Action | K37: Pending
A38: 34 | B38: =IF(MASTER_AR_REPORT!E79="","",MASTER_AR_REPORT!E79) -> Kaanuka Collection | C38: =IF(MASTER_AR_REPORT!D79="","",MASTER_AR_REPORT!D79) -> C-SLG/1203/25-26 | D38: =MASTER_AR_REPORT!C79 -> 45915 | E38: =MASTER_AR_REPORT!G79 -> 45940 | F38: =MASTER_AR_REPORT!I79 -> 1771 | G38: =MASTER_AR_REPORT!J79 -> 224 | H38: =MASTER_AR_REPORT!K79 -> 90+ Days | I38: =MASTER_AR_REPORT!L79 -> HIGH RISK | J38: =MASTER_AR_REPORT!M79 -> Immediate Action | K38: Pending
A39: 35 | B39: =IF(MASTER_AR_REPORT!E83="","",MASTER_AR_REPORT!E83) -> KITSONS-GACHIBOWLI | C39: =IF(MASTER_AR_REPORT!D83="","",MASTER_AR_REPORT!D83) -> C-SLG/1754/25-26 | D39: =MASTER_AR_REPORT!C83 -> 45985 | E39: =MASTER_AR_REPORT!G83 -> 46010 | F39: =MASTER_AR_REPORT!I83 -> 180 | G39: =MASTER_AR_REPORT!J83 -> 154 | H39: =MASTER_AR_REPORT!K83 -> 90+ Days | I39: =MASTER_AR_REPORT!L83 -> HIGH RISK | J39: =MASTER_AR_REPORT!M83 -> Immediate Action | K39: Pending
A40: 36 | B40: =IF(MASTER_AR_REPORT!E84="","",MASTER_AR_REPORT!E84) -> KITSONS-GACHIBOWLI | C40: =IF(MASTER_AR_REPORT!D84="","",MASTER_AR_REPORT!D84) -> C-SLG/2369/25-26 | D40: =MASTER_AR_REPORT!C84 -> 46092 | E40: =MASTER_AR_REPORT!G84 -> 46117 | F40: =MASTER_AR_REPORT!I84 -> 22195 | G40: =MASTER_AR_REPORT!J84 -> 47 | H40: =MASTER_AR_REPORT!K84 -> 31-60 Days | I40: =MASTER_AR_REPORT!L84 -> Low-Medium | J40: =MASTER_AR_REPORT!M84 -> Medium | K40: Pending
A41: 37 | B41: =IF(MASTER_AR_REPORT!E85="","",MASTER_AR_REPORT!E85) -> KITSONS-GACHIBOWLI | C41: =IF(MASTER_AR_REPORT!D85="","",MASTER_AR_REPORT!D85) -> C-SLG/2398/25-26 | D41: =MASTER_AR_REPORT!C85 -> 46098 | E41: =MASTER_AR_REPORT!G85 -> 46123 | F41: =MASTER_AR_REPORT!I85 -> 15116 | G41: =MASTER_AR_REPORT!J85 -> 41 | H41: =MASTER_AR_REPORT!K85 -> 31-60 Days | I41: =MASTER_AR_REPORT!L85 -> Low-Medium | J41: =MASTER_AR_REPORT!M85 -> Medium | K41: Pending
...

Sheet Watches_Report
A1: AR Aging Report - Watches
A2: Report Date: 21-May-2026
A4: S.No | B4: Source Sheet | C4: Date | D4: Invoice No | E4: Customer Name | F4: Invoice Amount | G4: Due Date | H4: Paid Amount | I4: Outstanding Amount | J4: Days Overdue | K4: Aging Bucket | L4: Risk Level | M4: Follow-up Priority | N4: Call Status | O4: Last Follow-up Notes
A5: 1 | B5: =IF(MASTER_AR_REPORT!B2="","",MASTER_AR_REPORT!B2) -> Watches | C5: =MASTER_AR_REPORT!C2 -> 46144 | D5: =IF(MASTER_AR_REPORT!D2="","",MASTER_AR_REPORT!D2) -> SLGCW/46/26-27 | E5: =IF(MASTER_AR_REPORT!E2="","",MASTER_AR_REPORT!E2) -> C. Ramchander Watch Co. | F5: =MASTER_AR_REPORT!F2 -> 1400 | G5: =MASTER_AR_REPORT!G2 -> 46144 | H5: =MASTER_AR_REPORT!H2 -> 0 | I5: =MASTER_AR_REPORT!I2 -> 1400 | J5: =MASTER_AR_REPORT!J2 -> 20 | K5: =MASTER_AR_REPORT!K2 -> 0-30 Days | L5: =MASTER_AR_REPORT!L2 -> Low | M5: =MASTER_AR_REPORT!M2 -> Normal | ... O5: =MASTER_AR_REPORT!O2 -> We need to give Credit Note
A6: 2 | B6: =IF(MASTER_AR_REPORT!B3="","",MASTER_AR_REPORT!B3) -> Watches | C6: =MASTER_AR_REPORT!C3 -> 45716 | D6: =IF(MASTER_AR_REPORT!D3="","",MASTER_AR_REPORT!D3) -> SLGCW/1077/24-25 | E6: =IF(MASTER_AR_REPORT!E3="","",MASTER_AR_REPORT!E3) -> KHALEEL WATCH CO. | F6: =MASTER_AR_REPORT!F3 -> 159.67 | G6: =MASTER_AR_REPORT!G3 -> 45716 | H6: =MASTER_AR_REPORT!H3 -> 0 | I6: =MASTER_AR_REPORT!I3 -> 159.67 | J6: =MASTER_AR_REPORT!J3 -> 448 | K6: =MASTER_AR_REPORT!K3 -> 90+ Days | L6: =MASTER_AR_REPORT!L3 -> HIGH RISK | M6: =MASTER_AR_REPORT!M3 -> Immediate Action | ... O6: =MASTER_AR_REPORT!O3 -> Sponge Not recived - Send DSO
A7: 3 | B7: =IF(MASTER_AR_REPORT!B4="","",MASTER_AR_REPORT!B4) -> Watches | C7: =MASTER_AR_REPORT!C4 -> 46013 | D7: =IF(MASTER_AR_REPORT!D4="","",MASTER_AR_REPORT!D4) -> SLGCW/1035/25-26 | E7: =IF(MASTER_AR_REPORT!E4="","",MASTER_AR_REPORT!E4) -> KHALEEL WATCH CO. | F7: =MASTER_AR_REPORT!F4 -> 383 | G7: =MASTER_AR_REPORT!G4 -> 46043 | H7: =MASTER_AR_REPORT!H4 -> 0 | I7: =MASTER_AR_REPORT!I4 -> 383 | J7: =MASTER_AR_REPORT!J4 -> 121 | K7: =MASTER_AR_REPORT!K4 -> 90+ Days | L7: =MASTER_AR_REPORT!L4 -> HIGH RISK | M7: =MASTER_AR_REPORT!M4 -> Immediate Action | ... O7: =MASTER_AR_REPORT!O4 -> He will Pay - Follow Up Needed
A8: 4 | B8: =IF(MASTER_AR_REPORT!B5="","",MASTER_AR_REPORT!B5) -> Watches | C8: =MASTER_AR_REPORT!C5 -> 45996 | D8: =IF(MASTER_AR_REPORT!D5="","",MASTER_AR_REPORT!D5) -> SLGCW/969/25-26 | E8: =IF(MASTER_AR_REPORT!E5="","",MASTER_AR_REPORT!E5) -> KISHORE WATCH CO | F8: =MASTER_AR_REPORT!F5 -> 2852 | G8: =MASTER_AR_REPORT!G5 -> 46041 | H8: =MASTER_AR_REPORT!H5 -> 0 | I8: =MASTER_AR_REPORT!I5 -> 2852 | J8: =MASTER_AR_REPORT!J5 -> 123 | K8: =MASTER_AR_REPORT!K5 -> 90+ Days | L8: =MASTER_AR_REPORT!L5 -> HIGH RISK | M8: =MASTER_AR_REPORT!M5 -> Immediate Action | ... O8: =MASTER_AR_REPORT!O5 -> Bill not available
A9: 5 | B9: =IF(MASTER_AR_REPORT!B6="","",MASTER_AR_REPORT!B6) -> Watches | C9: =MASTER_AR_REPORT!C6 -> 46139 | D9: =IF(MASTER_AR_REPORT!D6="","",MASTER_AR_REPORT!D6) -> SLGCW/25/26-27 | E9: =IF(MASTER_AR_REPORT!E6="","",MASTER_AR_REPORT!E6) -> KISHORE WATCH CO | F9: =MASTER_AR_REPORT!F6 -> 196667 | G9: =MASTER_AR_REPORT!G6 -> 46184 | H9: =MASTER_AR_REPORT!H6 -> 0 | I9: =MASTER_AR_REPORT!I6 -> 196667 | J9: =MASTER_AR_REPORT!J6 -> 0 | K9: =MASTER_AR_REPORT!K6 -> 0-30 Days | L9: =MASTER_AR_REPORT!L6 -> Low | M9: =MASTER_AR_REPORT!M6 -> Normal | ... O9: =MASTER_AR_REPORT!O6 -> 0
A10: 6 | B10: =IF(MASTER_AR_REPORT!B7="","",MASTER_AR_REPORT!B7) -> Watches | C10: =MASTER_AR_REPORT!C7 -> 46144 | D10: =IF(MASTER_AR_REPORT!D7="","",MASTER_AR_REPORT!D7) -> SLGCW/51/26-27 | E10: =IF(MASTER_AR_REPORT!E7="","",MASTER_AR_REPORT!E7) -> KISHORE WATCH CO | F10: =MASTER_AR_REPORT!F7 -> 9035 | G10: =MASTER_AR_REPORT!G7 -> 46189 | H10: =MASTER_AR_REPORT!H7 -> 0 | I10: =MASTER_AR_REPORT!I7 -> 9035 | J10: =MASTER_AR_REPORT!J7 -> 0 | K10: =MASTER_AR_REPORT!K7 -> 0-30 Days | L10: =MASTER_AR_REPORT!L7 -> Low | M10: =MASTER_AR_REPORT!M7 -> Normal | ... O10: =MASTER_AR_REPORT!O7 -> 0
A11: 7 | B11: =IF(MASTER_AR_REPORT!B8="","",MASTER_AR_REPORT!B8) -> Watches | C11: =MASTER_AR_REPORT!C8 -> 46148 | D11: =IF(MASTER_AR_REPORT!D8="","",MASTER_AR_REPORT!D8) -> SLGCW/59/26-27 | E11: =IF(MASTER_AR_REPORT!E8="","",MASTER_AR_REPORT!E8) -> KISHORE WATCH CO | F11: =MASTER_AR_REPORT!F8 -> 19731 | G11: =MASTER_AR_REPORT!G8 -> 46193 | H11: =MASTER_AR_REPORT!H8 -> 0 | I11: =MASTER_AR_REPORT!I8 -> 19731 | J11: =MASTER_AR_REPORT!J8 -> 0 | K11: =MASTER_AR_REPORT!K8 -> 0-30 Days | L11: =MASTER_AR_REPORT!L8 -> Low | M11: =MASTER_AR_REPORT!M8 -> Normal | ... O11: =MASTER_AR_REPORT!O8 -> 0
A12: 8 | B12: =IF(MASTER_AR_REPORT!B9="","",MASTER_AR_REPORT!B9) -> Watches | C12: =MASTER_AR_REPORT!C9 -> 46136 | D12: =IF(MASTER_AR_REPORT!D9="","",MASTER_AR_REPORT!D9) -> SLGCW/15/26-27 | E12: =IF(MASTER_AR_REPORT!E9="","",MASTER_AR_REPORT!E9) -> Maruti watche & electronics | F12: =MASTER_AR_REPORT!F9 -> 13163 | G12: =MASTER_AR_REPORT!G9 -> 46181 | H12: =MASTER_AR_REPORT!H9 -> 0 | I12: =MASTER_AR_REPORT!I9 -> 13163 | J12: =MASTER_AR_REPORT!J9 -> 0 | K12: =MASTER_AR_REPORT!K9 -> 0-30 Days | L12: =MASTER_AR_REPORT!L9 -> Low | M12: =MASTER_AR_REPORT!M9 -> Normal | ... O12: =MASTER_AR_REPORT!O9 -> 0
A13: 9 | B13: =IF(MASTER_AR_REPORT!B10="","",MASTER_AR_REPORT!B10) -> Watches | C13: =MASTER_AR_REPORT!C10 -> 46142 | D13: =IF(MASTER_AR_REPORT!D10="","",MASTER_AR_REPORT!D10) -> SLGCW/40/26-27 | E13: =IF(MASTER_AR_REPORT!E10="","",MASTER_AR_REPORT!E10) -> Maruti watche & electronics | F13: =MASTER_AR_REPORT!F10 -> 48979 | G13: =MASTER_AR_REPORT!G10 -> 46187 | H13: =MASTER_AR_REPORT!H10 -> 0 | I13: =MASTER_AR_REPORT!I10 -> 48979 | J13: =MASTER_AR_REPORT!J10 -> 0 | K13: =MASTER_AR_REPORT!K10 -> 0-30 Days | L13: =MASTER_AR_REPORT!L10 -> Low | M13: =MASTER_AR_REPORT!M10 -> Normal | ... O13: =MASTER_AR_REPORT!O10 -> 0
A14: 10 | B14: =IF(MASTER_AR_REPORT!B11="","",MASTER_AR_REPORT!B11) -> Watches | C14: =MASTER_AR_REPORT!C11 -> 46144 | D14: =IF(MASTER_AR_REPORT!D11="","",MASTER_AR_REPORT!D11) -> SLGCW/53/26-27 | E14: =IF(MASTER_AR_REPORT!E11="","",MASTER_AR_REPORT!E11) -> Maruti watche & electronics | F14: =MASTER_AR_REPORT!F11 -> 22969 | G14: =MASTER_AR_REPORT!G11 -> 46189 | H14: =MASTER_AR_REPORT!H11 -> 0 | I14: =MASTER_AR_REPORT!I11 -> 22969 | J14: =MASTER_AR_REPORT!J11 -> 0 | K14: =MASTER_AR_REPORT!K11 -> 0-30 Days | L14: =MASTER_AR_REPORT!L11 -> Low | M14: =MASTER_AR_REPORT!M11 -> Normal | ... O14: =MASTER_AR_REPORT!O11 -> 0
A15: 11 | B15: =IF(MASTER_AR_REPORT!B12="","",MASTER_AR_REPORT!B12) -> Watches | C15: =MASTER_AR_REPORT!C12 -> 46149 | D15: =IF(MASTER_AR_REPORT!D12="","",MASTER_AR_REPORT!D12) -> SLGCW/61/26-27 | E15: =IF(MASTER_AR_REPORT!E12="","",MASTER_AR_REPORT!E12) -> Maruti watche & electronics | F15: =MASTER_AR_REPORT!F12 -> 14355 | G15: =MASTER_AR_REPORT!G12 -> 46150 | H15: =MASTER_AR_REPORT!H12 -> 0 | I15: =MASTER_AR_REPORT!I12 -> 14355 | J15: =MASTER_AR_REPORT!J12 -> 14 | K15: =MASTER_AR_REPORT!K12 -> 0-30 Days | L15: =MASTER_AR_REPORT!L12 -> Low | M15: =MASTER_AR_REPORT!M12 -> Normal | ... O15: =MASTER_AR_REPORT!O12 -> Number Busy
A16: 12 | B16: =IF(MASTER_AR_REPORT!B13="","",MASTER_AR_REPORT!B13) -> Watches | C16: =MASTER_AR_REPORT!C13 -> 46157 | D16: =IF(MASTER_AR_REPORT!D13="","",MASTER_AR_REPORT!D13) -> SLGCW/65/26-27 | E16: =IF(MASTER_AR_REPORT!E13="","",MASTER_AR_REPORT!E13) -> Maruti watche & electronics | F16: =MASTER_AR_REPORT!F13 -> 3281 | G16: =MASTER_AR_REPORT!G13 -> 46158 | H16: =MASTER_AR_REPORT!H13 -> 0 | I16: =MASTER_AR_REPORT!I13 -> 3281 | J16: =MASTER_AR_REPORT!J13 -> 6 | K16: =MASTER_AR_REPORT!K13 -> 0-30 Days | L16: =MASTER_AR_REPORT!L13 -> Low | M16: =MASTER_AR_REPORT!M13 -> Normal | ... O16: =MASTER_AR_REPORT!O13 -> Number Busy
... A61: 57 | B61: =IF(MASTER_AR_REPORT!B58="","",MASTER_AR_REPORT!B58) -> Watches | C61: =MASTER_AR_REPORT!C58 -> 46137 | D61: =IF(MASTER_AR_REPORT!D58="","",MASTER_AR_REPORT!D58) -> SLGCW/20/26-27 | E61: =IF(MASTER_AR_REPORT!E58="","",MASTER_AR_REPORT!E58) -> THE TIMES | F61: =MASTER_AR_REPORT!F58 -> 70357 | G61: =MASTER_AR_REPORT!G58 -> 46137 | H61: =MASTER_AR_REPORT!H58 -> 0 | I61: =MASTER_AR_REPORT!I58 -> 70357 | J61: =MASTER_AR_REPORT!J58 -> 27 | K61: =MASTER_AR_REPORT!K58 -> 0-30 Days | L61: =MASTER_AR_REPORT!L58 -> Low | M61: =MASTER_AR_REPORT!M58 -> Normal | ... O61: =MASTER_AR_REPORT!O58 -> Next Week (Market Down)
E62: TOTAL | F62: =SUM(F5:F61) -> 5871536 | H62: =SUM(H5:H61) -> 162465 | I62: =SUM(I5:I61) -> 5709071

Sheet Praveen_Report
A1: AR Aging Report - Praveen
A2: Report Date: 21-May-2026
A4: S.No | B4: Source Sheet | C4: Date | D4: Invoice No | E4: Customer Name | F4: Invoice Amount | G4: Due Date | H4: Paid Amount | I4: Outstanding Amount | J4: Days Overdue | K4: Aging Bucket | L4: Risk Level | M4: Follow-up Priority | N4: Call Status | O4: Last Follow-up Notes
A5: 1 | B5: =IF(MASTER_AR_REPORT!B59="","",MASTER_AR_REPORT!B59) -> Praveen | C5: =MASTER_AR_REPORT!C59 -> 46095 | D5: =IF(MASTER_AR_REPORT!D59="","",MASTER_AR_REPORT!D59) -> C-SLG/2384/25-26 | E5: =IF(MASTER_AR_REPORT!E59="","",MASTER_AR_REPORT!E59) -> AMBIKA STATIONERY | F5: =MASTER_AR_REPORT!F59 -> 8075 | G5: =MASTER_AR_REPORT!G59 -> 46120 | H5: =MASTER_AR_REPORT!H59 -> 0 | I5: =MASTER_AR_REPORT!I59 -> 8075 | J5: =MASTER_AR_REPORT!J59 -> 44 | K5: =MASTER_AR_REPORT!K59 -> 31-60 Days | L5: =MASTER_AR_REPORT!L59 -> Low-Medium | M5: =MASTER_AR_REPORT!M59 -> Medium | ... O5: =MASTER_AR_REPORT!O59 -> Number Busy
A6: 2 | B6: =IF(MASTER_AR_REPORT!B60="","",MASTER_AR_REPORT!B60) -> Praveen | C6: =MASTER_AR_REPORT!C60 -> 45996 | D6: =IF(MASTER_AR_REPORT!D60="","",MASTER_AR_REPORT!D60) -> C-SLG/1844/25-26 | E6: =IF(MASTER_AR_REPORT!E60="","",MASTER_AR_REPORT!E60) -> BEST ENTERPRISES | F6: =MASTER_AR_REPORT!F60 -> 30511 | G6: =MASTER_AR_REPORT!G60 -> 46021 | H6: =MASTER_AR_REPORT!H60 -> 0 | I6: =MASTER_AR_REPORT!I60 -> 30511 | J6: =MASTER_AR_REPORT!J60 -> 143 | K6: =MASTER_AR_REPORT!K60 -> 90+ Days | L6: =MASTER_AR_REPORT!L60 -> HIGH RISK | M6: =MASTER_AR_REPORT!M60 -> Immediate Action | ... O6: =MASTER_AR_REPORT!O60 -> Customer Out of Station - Month end he will Pay
A7: 3 | B7: =IF(MASTER_AR_REPORT!B61="","",MASTER_AR_REPORT!B61) -> Praveen | C7: =MASTER_AR_REPORT!C61 -> 46105 | D7: =IF(MASTER_AR_REPORT!D61="","",MASTER_AR_REPORT!D61) -> C-SLG/2429/25-26 | E7: =IF(MASTER_AR_REPORT!E61="","",MASTER_AR_REPORT!E61) -> Bhavani Stationery and Gift | F7: =MASTER_AR_REPORT!F61 -> 1186 | G7: =MASTER_AR_REPORT!G61 -> 46130 | H7: =MASTER_AR_REPORT!H61 -> 0 | I7: =MASTER_AR_REPORT!I61 -> 1186 | J7: =MASTER_AR_REPORT!J61 -> 34 | K7: =MASTER_AR_REPORT!K61 -> 31-60 Days | L7: =MASTER_AR_REPORT!L61 -> Low-Medium | M7: =MASTER_AR_REPORT!M61 -> Medium | ... O7: =MASTER_AR_REPORT!O61 -> 0
A8: 4 | B8: =IF(MASTER_AR_REPORT!B62="","",MASTER_AR_REPORT!B62) -> Praveen | C8: =MASTER_AR_REPORT!C62 -> 46156 | D8: =IF(MASTER_AR_REPORT!D62="","",MASTER_AR_REPORT!D62) -> C-SLG/0125/26-27 | E8: =IF(MASTER_AR_REPORT!E62="","",MASTER_AR_REPORT!E62) -> Bhavani Stationery and Gift | F8: =MASTER_AR_REPORT!F62 -> 2941 | G8: =MASTER_AR_REPORT!G62 -> 46181 | H8: =MASTER_AR_REPORT!H62 -> 0 | I8: =MASTER_AR_REPORT!I62 -> 2941 | J8: =MASTER_AR_REPORT!J62 -> 0 | K8: =MASTER_AR_REPORT!K62 -> 0-30 Days | L8: =MASTER_AR_REPORT!L62 -> Low | M8: =MASTER_AR_REPORT!M62 -> Normal | ... O8: =MASTER_AR_REPORT!O62 -> 0
A9: 5 | B9: =IF(MASTER_AR_REPORT!B63="","",MASTER_AR_REPORT!B63) -> Praveen | C9: =MASTER_AR_REPORT!C63 -> 46105 | D9: =IF(MASTER_AR_REPORT!D63="","",MASTER_AR_REPORT!D63) -> C-SLG/2427/25-26 | E9: =IF(MASTER_AR_REPORT!E63="","",MASTER_AR_REPORT!E63) -> Dachapally Book Centre | F9: =MASTER_AR_REPORT!F63 -> 5152 | G9: =MASTER_AR_REPORT!G63 -> 46130 | H9: =MASTER_AR_REPORT!H63 -> 0 | I9: =MASTER_AR_REPORT!I63 -> 5152 | J9: =MASTER_AR_REPORT!J63 -> 34 | K9: =MASTER_AR_REPORT!K63 -> 31-60 Days | L9: =MASTER_AR_REPORT!L63 -> Low-Medium | M9: =MASTER_AR_REPORT!M63 -> Medium | ... O9: =MASTER_AR_REPORT!O63 -> No Number available - Send DSO
A10: 6 | B10: =IF(MASTER_AR_REPORT!B64="","",MASTER_AR_REPORT!B64) -> Praveen | C10: =MASTER_AR_REPORT!C64 -> 45975 | D10: =IF(MASTER_AR_REPORT!D64="","",MASTER_AR_REPORT!D64) -> C-SLG/1655/25-26 | E10: =IF(MASTER_AR_REPORT!E64="","",MASTER_AR_REPORT!E64) -> Deccan Book Depot and Stationery | F10: =MASTER_AR_REPORT!F64 -> 2900 | G10: =MASTER_AR_REPORT!G64 -> 46000 | H10: =MASTER_AR_REPORT!H64 -> 0 | I10: =MASTER_AR_REPORT!I64 -> 2900 | J10: =MASTER_AR_REPORT!J64 -> 164 | K10: =MASTER_AR_REPORT!K64 -> 90+ Days | L10: =MASTER_AR_REPORT!L64 -> HIGH RISK | M10: =MASTER_AR_REPORT!M64 -> Immediate Action | ... O10: =MASTER_AR_REPORT!O64 -> Send DSO with Sign Copies
A11: 7 | B11: =IF(MASTER_AR_REPORT!B65="","",MASTER_AR_REPORT!B65) -> Praveen | C11: =MASTER_AR_REPORT!C65 -> 46069 | D11: =IF(MASTER_AR_REPORT!D65="","",MASTER_AR_REPORT!D65) -> C-SLG/2235/25-26 | E11: =IF(MASTER_AR_REPORT!E65="","",MASTER_AR_REPORT!E65) -> Deccan Book Depot and Stationery | F11: =MASTER_AR_REPORT!F65 -> 2044 | G11: =MASTER_AR_REPORT!G65 -> 46094 | H11: =MASTER_AR_REPORT!H65 -> 0 | I11: =MASTER_AR_REPORT!I65 -> 2044 | J11: =MASTER_AR_REPORT!J65 -> 70 | K11: =MASTER_AR_REPORT!K65 -> 61-90 Days | L11: =MASTER_AR_REPORT!L65 -> Medium | M11: =MASTER_AR_REPORT!M65 -> Urgent | ... O11: =MASTER_AR_REPORT!O65 -> Send DSO with Sign Copies
A12: 8 | B12: =IF(MASTER_AR_REPORT!B66="","",MASTER_AR_REPORT!B66) -> Praveen | C12: =MASTER_AR_REPORT!C66 -> 46088 | D12: =IF(MASTER_AR_REPORT!D66="","",MASTER_AR_REPORT!D66) -> C-SLG/2344/25-26 | E12: =IF(MASTER_AR_REPORT!E66="","",MASTER_AR_REPORT!E66) -> Dilip Super Market (Manikonda) | F12: =MASTER_AR_REPORT!F66 -> 2472 | G12: =MASTER_AR_REPORT!G66 -> 46113 | H12: =MASTER_AR_REPORT!H66 -> 0 | I12: =MASTER_AR_REPORT!I66 -> 2472 | J12: =MASTER_AR_REPORT!J66 -> 51 | K12: =MASTER_AR_REPORT!K66 -> 31-60 Days | L12: =MASTER_AR_REPORT!L66 -> Low-Medium | M12: =MASTER_AR_REPORT!M66 -> Medium | ... O12: =MASTER_AR_REPORT!O66 -> He will inform to his Sir
A13: 9 | B13: =IF(MASTER_AR_REPORT!B67="","",MASTER_AR_REPORT!B67) -> Praveen | C13: =MASTER_AR_REPORT!C67 -> 46105 | D13: =IF(MASTER_AR_REPORT!D67="","",MASTER_AR_REPORT!D67) -> C-SLG/2432/25-25 | E13: =IF(MASTER_AR_REPORT!E67="","",MASTER_AR_REPORT!E67) -> Ever Green Book Centre | F13: =MASTER_AR_REPORT!F67 -> 381 | G13: =MASTER_AR_REPORT!G67 -> 46130 | H13: =MASTER_AR_REPORT!H67 -> 0 | I13: =MASTER_AR_REPORT!I67 -> 381 | J13: =MASTER_AR_REPORT!J67 -> 34 | K13: =MASTER_AR_REPORT!K67 -> 31-60 Days | L13: =MASTER_AR_REPORT!L67 -> Low-Medium | M13: =MASTER_AR_REPORT!M67 -> Medium | ... O13: =MASTER_AR_REPORT!O67 -> 0
A14: 10 | B14: =IF(MASTER_AR_REPORT!B68="","",MASTER_AR_REPORT!B68) -> Praveen | C14: =MASTER_AR_REPORT!C68 -> 46123 | D14: =IF(MASTER_AR_REPORT!D68="","",MASTER_AR_REPORT!D68) -> C-SLG/0029/26-27 | E14: =IF(MASTER_AR_REPORT!E68="","",MASTER_AR_REPORT!E68) -> Ever Green Book Centre | F14: =MASTER_AR_REPORT!F68 -> 8874 | G14: =MASTER_AR_REPORT!G68 -> 46148 | H14: =MASTER_AR_REPORT!H68 -> 0 | I14: =MASTER_AR_REPORT!I68 -> 8874 | J14: =MASTER_AR_REPORT!J68 -> 16 | K14: =MASTER_AR_REPORT!K68 -> 0-30 Days | L14: =MASTER_AR_REPORT!L68 -> Low | M14: =MASTER_AR_REPORT!M68 -> Normal | ... O14: =MASTER_AR_REPORT!O68 -> 0
